Workbook

Sheet Dashboard
B6: Swapnil Wale | E6: Project BRMS Tech | S6: =TODAY() -> 44835
B21: Open Risks (Rating) | H21: Open Issues (Severity) | N21: Open Action Items | Q21: Open Change Requests | T21: Pending Decisions
N22: =Data!H16 -> 4 | Q22: =Data!K17 -> 2 | T22: =Data!N17 -> 1

Sheet Schedule
B6: BRMS Implementation | D6: View Start | G6: 42495 | H6: Timeline | K6: days | L6: 1 | M6: =G6 -> 42495 | N6: =M6+$L$6 -> 42496 | O6: =N6+$L$6 -> 42497 | P6: =O6+$L$6 -> 42498 | Q6: =P6+$L$6 -> 42499 | R6: =Q6+$L$6 -> 42500 | S6: =R6+$L$6 -> 42501 | T6: =S6+$L$6 -> 42502 | U6: =T6+$L$6 -> 42503 | ... JK6: =JJ6+$L$6 -> 42753
B7: # | C7: Task Name | D7: Resource | E7: Pre | F7: Start | G7: Finish | H7: Effort (days) | I7: % | J7: % | K7: % | L7: Status
G8: Auto | I8: Act | J8: Plan | K8: Plan | M8: =LEFT(TEXT(M6,"ddd")) -> T | N8: =LEFT(TEXT(N6,"ddd")) -> F | O8: =LEFT(TEXT(O6,"ddd")) -> S | P8: =LEFT(TEXT(P6,"ddd")) -> S | Q8: =LEFT(TEXT(Q6,"ddd")) -> M | R8: =LEFT(TEXT(R6,"ddd")) -> T | S8: =LEFT(TEXT(S6,"ddd")) -> W | T8: =LEFT(TEXT(T6,"ddd")) -> T | ... JK8: =LEFT(TEXT(JK6,"ddd")) -> W
B9: 1 | C9: Requirement Gathering | D9: John | F9: 42495 | G9: =WORKDAY(F9,H9-1,Config!D7:D26) -> 42529 | H9: 25 | I9: 0.94 | J9: =IF(((NETWORKDAYS(F9,TODAY(),Data!C2:C21)*100)/H9)/100 > 0,((NETWORKDAYS(F9,TODAY(),Data!C2:C21)*100)/H9)/100,0) -> 66.88 | K9: =IF(J9>1, "100%",$J9) -> 100% | L9: =K9-I9 -> 0.06 | M9: =IF(AND(M$6>=$F9,M$6<=$G9),"."," ") -> . | N9: =IF(AND(N$6>=$F9,N$6<=$G9),"."," ") -> . | O9: =IF(AND(O$6>=$F9,O$6<=$G9),"."," ") -> . | P9: =IF(AND(P$6>=$F9,P$6<=$G9),"."," ") -> . | Q9: =IF(AND(Q$6>=$F9,Q$6<=$G9),"."," ") -> . | T9: =IF(AND(T$6>=$F9,T$6<=$G9),"."," ") -> . | U9: =IF(AND(U$6>=$F9,U$6<=$G9),"."," ") -> . | V9: =IF(AND(V$6>=$F9,V$6<=$G9),"."," ") -> . | W9: =IF(AND(W$6>=$F9,W$6<=$G9),"."," ") -> . | X9: =IF(AND(X$6>=$F9,X$6<=$G9),"."," ") -> . | AA9: =IF(AND(AA$6>=$F9,AA$6<=$G9),"."," ") -> . | AB9: =IF(AND(AB$6>=$F9,AB$6<=$G9),"."," ") -> . | AC9: =IF(AND(AC$6>=$F9,AC$6<=$G9),"."," ") -> . | AD9: =IF(AND(AD$6>=$F9,AD$6<=$G9),"."," ") -> . | AE9: =IF(AND(AE$6>=$F9,AE$6<=$G9),"."," ") -> . | AH9: =IF(AND(AH$6>=$F9,AH$6<=$G9),"."," ") -> . | AI9: =IF(AND(AI$6>=$F9,AI$6<=$G9),"."," ") -> . | AJ9: =IF(AND(AJ$6>=$F9,AJ$6<=$G9),"."," ") -> . | AK9: =IF(AND(AK$6>=$F9,AK$6<=$G9),"."," ") -> . | AL9: =IF(AND(AL$6>=$F9,AL$6<=$G9),"."," ") -> . | AO9: =IF(AND(AO$6>=$F9,AO$6<=$G9),"."," ") -> . | AP9: =IF(AND(AP$6>=$F9,AP$6<=$G9),"."," ") -> . | AQ9: =IF(AND(AQ$6>=$F9,AQ$6<=$G9),"."," ") -> . | AR9: =IF(AND(AR$6>=$F9,AR$6<=$G9),"."," ") -> . | AS9: =IF(AND(AS$6>=$F9,AS$6<=$G9),"."," ") -> . | AV9: =IF(AND(AV$6>=$F9,AV$6<=$G9),"."," ") | AW9: =IF(AND(AW$6>=$F9,AW$6<=$G9),"."," ") | AX9: =IF(AND(AX$6>=$F9,AX$6<=$G9),"."," ") | AY9: =IF(AND(AY$6>=$F9,AY$6<=$G9),"."," ") | AZ9: =IF(AND(AZ$6>=$F9,AZ$6<=$G9),"."," ") | BC9: =IF(AND(BC$6>=$F9,BC$6<=$G9),"."," ") | BD9: =IF(AND(BD$6>=$F9,BD$6<=$G9),"."," ") | BE9: =IF(AND(BE$6>=$F9,BE$6<=$G9),"."," ") | BF9: =IF(AND(BF$6>=$F9,BF$6<=$G9),"."," ") | BG9: =IF(AND(BG$6>=$F9,BG$6<=$G9),"."," ") | BJ9: =IF(AND(BJ$6>=$F9,BJ$6<=$G9),"."," ") | BK9: =IF(AND(BK$6>=$F9,BK$6<=$G9),"."," ") | BL9: =IF(AND(BL$6>=$F9,BL$6<=$G9),"."," ") | BM9: =IF(AND(BM$6>=$F9,BM$6<=$G9),"."," ") | BN9: =IF(AND(BN$6>=$F9,BN$6<=$G9),"."," ") | BQ9: =IF(AND(BQ$6>=$F9,BQ$6<=$G9),"."," ") | BR9: =IF(AND(BR$6>=$F9,BR$6<=$G9),"."," ") | BS9: =IF(AND(BS$6>=$F9,BS$6<=$G9),"."," ") | BT9: =IF(AND(BT$6>=$F9,BT$6<=$G9),"."," ") | BU9: =IF(AND(BU$6>=$F9,BU$6<=$G9),"."," ") | BX9: =IF(AND(BX$6>=$F9,BX$6<=$G9),"."," ") | BY9: =IF(AND(BY$6>=$F9,BY$6<=$G9),"."," ") | BZ9: =IF(AND(BZ$6>=$F9,BZ$6<=$G9),"."," ") | CA9: =IF(AND(CA$6>=$F9,CA$6<=$G9),"."," ") | CB9: =IF(AND(CB$6>=$F9,CB$6<=$G9),"."," ") | CE9: =IF(AND(CE$6>=$F9,CE$6<=$G9),"."," ") | CF9: =IF(AND(CF$6>=$F9,CF$6<=$G9),"."," ") | CG9: =IF(AND(CG$6>=$F9,CG$6<=$G9),"."," ") | CH9: =IF(AND(CH$6>=$F9,CH$6<=$G9),"."," ") | CI9: =IF(AND(CI$6>=$F9,CI$6<=$G9),"."," ") | CL9: =IF(AND(CL$6>=$F9,CL$6<=$G9),"."," ") | CM9: =IF(AND(CM$6>=$F9,CM$6<=$G9),"."," ") | CN9: =IF(AND(CN$6>=$F9,CN$6<=$G9),"."," ") | CO9: =IF(AND(CO$6>=$F9,CO$6<=$G9),"."," ") | CP9: =IF(AND(CP$6>=$F9,CP$6<=$G9),"."," ") | CS9: =IF(AND(CS$6>=$F9,CS$6<=$G9),"."," ") | CT9: =IF(AND(CT$6>=$F9,CT$6<=$G9),"."," ") | CU9: =IF(AND(CU$6>=$F9,CU$6<=$G9),"."," ") | CV9: =IF(AND(CV$6>=$F9,CV$6<=$G9),"."," ") | CW9: =IF(AND(CW$6>=$F9,CW$6<=$G9),"."," ") | CZ9: =IF(AND(CZ$6>=$F9,CZ$6<=$G9),"."," ") | DA9: =IF(AND(DA$6>=$F9,DA$6<=$G9),"."," ") | DB9: =IF(AND(DB$6>=$F9,DB$6<=$G9),"."," ") | DC9: =IF(AND(DC$6>=$F9,DC$6<=$G9),"."," ") | DD9: =IF(AND(DD$6>=$F9,DD$6<=$G9),"."," ") | DG9: =IF(AND(DG$6>=$F9,DG$6<=$G9),"."," ") | DH9: =IF(AND(DH$6>=$F9,DH$6<=$G9),"."," ") | DI9: =IF(AND(DI$6>=$F9,DI$6<=$G9),"."," ") | DJ9: =IF(AND(DJ$6>=$F9,DJ$6<=$G9),"."," ") | DK9: =IF(AND(DK$6>=$F9,DK$6<=$G9),"."," ") | DN9: =IF(AND(DN$6>=$F9,DN$6<=$G9),"."," ") | DO9: =IF(AND(DO$6>=$F9,DO$6<=$G9),"."," ") | DP9: =IF(AND(DP$6>=$F9,DP$6<=$G9),"."," ") | DQ9: =IF(AND(DQ$6>=$F9,DQ$6<=$G9),"."," ") | DR9: =IF(AND(DR$6>=$F9,DR$6<=$G9),"."," ") | DU9: =IF(AND(DU$6>=$F9,DU$6<=$G9),"."," ") | DV9: =IF(AND(DV$6>=$F9,DV$6<=$G9),"."," ") | DW9: =IF(AND(DW$6>=$F9,DW$6<=$G9),"."," ") | DX9: =IF(AND(DX$6>=$F9,DX$6<=$G9),"."," ") | DY9: =IF(AND(DY$6>=$F9,DY$6<=$G9),"."," ") | EB9: =IF(AND(EB$6>=$F9,EB$6<=$G9),"."," ") | EC9: =IF(AND(EC$6>=$F9,EC$6<=$G9),"."," ") | ED9: =IF(AND(ED$6>=$F9,ED$6<=$G9),"."," ") | EE9: =IF(AND(EE$6>=$F9,EE$6<=$G9),"."," ") | EF9: =IF(AND(EF$6>=$F9,EF$6<=$G9),"."," ") | EI9: =IF(AND(EI$6>=$F9,EI$6<=$G9),"."," ") | EJ9: =IF(AND(EJ$6>=$F9,EJ$6<=$G9),"."," ") | EK9: =IF(AND(EK$6>=$F9,EK$6<=$G9),"."," ") | EL9: =IF(AND(EL$6>=$F9,EL$6<=$G9),"."," ") | EM9: =IF(AND(EM$6>=$F9,EM$6<=$G9),"."," ") | EP9: =IF(AND(EP$6>=$F9,EP$6<=$G9),"."," ") | EQ9: =IF(AND(EQ$6>=$F9,EQ$6<=$G9),"."," ") | ER9: =IF(AND(ER$6>=$F9,ER$6<=$G9),"."," ") | ES9: =IF(AND(ES$6>=$F9,ES$6<=$G9),"."," ") | ET9: =IF(AND(ET$6>=$F9,ET$6<=$G9),"."," ") | EW9: =IF(AND(EW$6>=$F9,EW$6<=$G9),"."," ") | EX9: =IF(AND(EX$6>=$F9,EX$6<=$G9),"."," ") | EY9: =IF(AND(EY$6>=$F9,EY$6<=$G9),"."," ") | EZ9: =IF(AND(EZ$6>=$F9,EZ$6<=$G9),"."," ") | FA9: =IF(AND(FA$6>=$F9,FA$6<=$G9),"."," ") | FD9: =IF(AND(FD$6>=$F9,FD$6<=$G9),"."," ") | FE9: =IF(AND(FE$6>=$F9,FE$6<=$G9),"."," ") | FF9: =IF(AND(FF$6>=$F9,FF$6<=$G9),"."," ") | FG9: =IF(AND(FG$6>=$F9,FG$6<=$G9),"."," ") | FH9: =IF(AND(FH$6>=$F9,FH$6<=$G9),"."," ") | FK9: =IF(AND(FK$6>=$F9,FK$6<=$G9),"."," ") | FL9: =IF(AND(FL$6>=$F9,FL$6<=$G9),"."," ") | FM9: =IF(AND(FM$6>=$F9,FM$6<=$G9),"."," ") | FN9: =IF(AND(FN$6>=$F9,FN$6<=$G9),"."," ") | FO9: =IF(AND(FO$6>=$F9,FO$6<=$G9),"."," ") | FR9: =IF(AND(FR$6>=$F9,FR$6<=$G9),"."," ") | FS9: =IF(AND(FS$6>=$F9,FS$6<=$G9),"."," ") | FT9: =IF(AND(FT$6>=$F9,FT$6<=$G9),"."," ") | FU9: =IF(AND(FU$6>=$F9,FU$6<=$G9),"."," ") | FV9: =IF(AND(FV$6>=$F9,FV$6<=$G9),"."," ") | FY9: =IF(AND(FY$6>=$F9,FY$6<=$G9),"."," ") | FZ9: =IF(AND(FZ$6>=$F9,FZ$6<=$G9),"."," ") | GA9: =IF(AND(GA$6>=$F9,GA$6<=$G9),"."," ") | GB9: =IF(AND(GB$6>=$F9,GB$6<=$G9),"."," ") | GC9: =IF(AND(GC$6>=$F9,GC$6<=$G9),"."," ") | GF9: =IF(AND(GF$6>=$F9,GF$6<=$G9),"."," ") | GG9: =IF(AND(GG$6>=$F9,GG$6<=$G9),"."," ") | GH9: =IF(AND(GH$6>=$F9,GH$6<=$G9),"."," ") | GI9: =IF(AND(GI$6>=$F9,GI$6<=$G9),"."," ") | GJ9: =IF(AND(GJ$6>=$F9,GJ$6<=$G9),"."," ") | GM9: =IF(AND(GM$6>=$F9,GM$6<=$G9),"."," ") | GN9: =IF(AND(GN$6>=$F9,GN$6<=$G9),"."," ") | GO9: =IF(AND(GO$6>=$F9,GO$6<=$G9),"."," ") | GP9: =IF(AND(GP$6>=$F9,GP$6<=$G9),"."," ") | GQ9: =IF(AND(GQ$6>=$F9,GQ$6<=$G9),"."," ") | GT9: =IF(AND(GT$6>=$F9,GT$6<=$G9),"."," ") | GU9: =IF(AND(GU$6>=$F9,GU$6<=$G9),"."," ") | GV9: =IF(AND(GV$6>=$F9,GV$6<=$G9),"."," ") | GW9: =IF(AND(GW$6>=$F9,GW$6<=$G9),"."," ") | GX9: =IF(AND(GX$6>=$F9,GX$6<=$G9),"."," ") | HA9: =IF(AND(HA$6>=$F9,HA$6<=$G9),"."," ") | HB9: =IF(AND(HB$6>=$F9,HB$6<=$G9),"."," ") | HC9: =IF(AND(HC$6>=$F9,HC$6<=$G9),"."," ") | HD9: =IF(AND(HD$6>=$F9,HD$6<=$G9),"."," ") | HE9: =IF(AND(HE$6>=$F9,HE$6<=$G9),"."," ") | HH9: =IF(AND(HH$6>=$F9,HH$6<=$G9),"."," ") | HI9: =IF(AND(HI$6>=$F9,HI$6<=$G9),"."," ") | HJ9: =IF(AND(HJ$6>=$F9,HJ$6<=$G9),"."," ") | HK9: =IF(AND(HK$6>=$F9,HK$6<=$G9),"."," ") | HL9: =IF(AND(HL$6>=$F9,HL$6<=$G9),"."," ") | HO9: =IF(AND(HO$6>=$F9,HO$6<=$G9),"."," ") | HP9: =IF(AND(HP$6>=$F9,HP$6<=$G9),"."," ") | HQ9: =IF(AND(HQ$6>=$F9,HQ$6<=$G9),"."," ") | HR9: =IF(AND(HR$6>=$F9,HR$6<=$G9),"."," ") | HS9: =IF(AND(HS$6>=$F9,HS$6<=$G9),"."," ") | HV9: =IF(AND(HV$6>=$F9,HV$6<=$G9),"."," ") | HW9: =IF(AND(HW$6>=$F9,HW$6<=$G9),"."," ") | HX9: =IF(AND(HX$6>=$F9,HX$6<=$G9),"."," ") | HY9: =IF(AND(HY$6>=$F9,HY$6<=$G9),"."," ") | HZ9: =IF(AND(HZ$6>=$F9,HZ$6<=$G9),"."," ") | IC9: =IF(AND(IC$6>=$F9,IC$6<=$G9),"."," ") | ID9: =IF(AND(ID$6>=$F9,ID$6<=$G9),"."," ") | IE9: =IF(AND(IE$6>=$F9,IE$6<=$G9),"."," ") | IF9: =IF(AND(IF$6>=$F9,IF$6<=$G9),"."," ") | IG9: =IF(AND(IG$6>=$F9,IG$6<=$G9),"."," ") | IJ9: =IF(AND(IJ$6>=$F9,IJ$6<=$G9),"."," ") | IK9: =IF(AND(IK$6>=$F9,IK$6<=$G9),"."," ") | IL9: =IF(AND(IL$6>=$F9,IL$6<=$G9),"."," ") | IM9: =IF(AND(IM$6>=$F9,IM$6<=$G9),"."," ") | IN9: =IF(AND(IN$6>=$F9,IN$6<=$G9),"."," ") | IQ9: =IF(AND(IQ$6>=$F9,IQ$6<=$G9),"."," ") | IR9: =IF(AND(IR$6>=$F9,IR$6<=$G9),"."," ") | IS9: =IF(AND(IS$6>=$F9,IS$6<=$G9),"."," ") | IT9: =IF(AND(IT$6>=$F9,IT$6<=$G9),"."," ") | IU9: =IF(AND(IU$6>=$F9,IU$6<=$G9),"."," ") | IX9: =IF(AND(IX$6>=$F9,IX$6<=$G9),"."," ") | IY9: =IF(AND(IY$6>=$F9,IY$6<=$G9),"."," ") | IZ9: =IF(AND(IZ$6>=$F9,IZ$6<=$G9),"."," ") | JA9: =IF(AND(JA$6>=$F9,JA$6<=$G9),"."," ") | JB9: =IF(AND(JB$6>=$F9,JB$6<=$G9),"."," ") | JE9: =IF(AND(JE$6>=$F9,JE$6<=$G9),"."," ") | JF9: =IF(AND(JF$6>=$F9,JF$6<=$G9),"."," ") | JG9: =IF(AND(JG$6>=$F9,JG$6<=$G9),"."," ") | JH9: =IF(AND(JH$6>=$F9,JH$6<=$G9),"."," ") | JI9: =IF(AND(JI$6>=$F9,JI$6<=$G9),"."," ")
B10: =B9+1 -> 2 | C10: Draft Business Requirements | D10: John | E10: 1 | F10: 42502 | G10: =WORKDAY(F10,H10-1,Config!D8:D27) -> 42506 | H10: 3 | I10: 0.94 | J10: =IF(((NETWORKDAYS(F10,TODAY(),Data!C3:C22)*100)/H10)/100 > 0,((NETWORKDAYS(F10,TODAY(),Data!C3:C22)*100)/H10)/100,0) -> 555.66667 | K10: =IF(J10>1, "100%",$J10) -> 100% | L10: =K10-I10 -> 0.06 | M10: =IF(AND(M$6>=$F10,M$6<=$G10),"."," ") | N10: =IF(AND(N$6>=$F10,N$6<=$G10),"."," ") | O10: =IF(AND(O$6>=$F10,O$6<=$G10),"."," ") | P10: =IF(AND(P$6>=$F10,P$6<=$G10),"."," ") | Q10: =IF(AND(Q$6>=$F10,Q$6<=$G10),"."," ") | T10: =IF(AND(T$6>=$F10,T$6<=$G10),"."," ") -> . | U10: =IF(AND(U$6>=$F10,U$6<=$G10),"."," ") -> . | V10: =IF(AND(V$6>=$F10,V$6<=$G10),"."," ") -> . | W10: =IF(AND(W$6>=$F10,W$6<=$G10),"."," ") -> . | X10: =IF(AND(X$6>=$F10,X$6<=$G10),"."," ") -> . | AA10: =IF(AND(AA$6>=$F10,AA$6<=$G10),"."," ") | AB10: =IF(AND(AB$6>=$F10,AB$6<=$G10),"."," ") | AC10: =IF(AND(AC$6>=$F10,AC$6<=$G10),"."," ") | AD10: =IF(AND(AD$6>=$F10,AD$6<=$G10),"."," ") | AE10: =IF(AND(AE$6>=$F10,AE$6<=$G10),"."," ") | AH10: =IF(AND(AH$6>=$F10,AH$6<=$G10),"."," ") | AI10: =IF(AND(AI$6>=$F10,AI$6<=$G10),"."," ") | AJ10: =IF(AND(AJ$6>=$F10,AJ$6<=$G10),"."," ") | AK10: =IF(AND(AK$6>=$F10,AK$6<=$G10),"."," ") | AL10: =IF(AND(AL$6>=$F10,AL$6<=$G10),"."," ") | AO10: =IF(AND(AO$6>=$F10,AO$6<=$G10),"."," ") | AP10: =IF(AND(AP$6>=$F10,AP$6<=$G10),"."," ") | AQ10: =IF(AND(AQ$6>=$F10,AQ$6<=$G10),"."," ") | AR10: =IF(AND(AR$6>=$F10,AR$6<=$G10),"."," ") | AS10: =IF(AND(AS$6>=$F10,AS$6<=$G10),"."," ") | AV10: =IF(AND(AV$6>=$F10,AV$6<=$G10),"."," ") | AW10: =IF(AND(AW$6>=$F10,AW$6<=$G10),"."," ") | AX10: =IF(AND(AX$6>=$F10,AX$6<=$G10),"."," ") | AY10: =IF(AND(AY$6>=$F10,AY$6<=$G10),"."," ") | AZ10: =IF(AND(AZ$6>=$F10,AZ$6<=$G10),"."," ") | BC10: =IF(AND(BC$6>=$F10,BC$6<=$G10),"."," ") | BD10: =IF(AND(BD$6>=$F10,BD$6<=$G10),"."," ") | BE10: =IF(AND(BE$6>=$F10,BE$6<=$G10),"."," ") | BF10: =IF(AND(BF$6>=$F10,BF$6<=$G10),"."," ") | BG10: =IF(AND(BG$6>=$F10,BG$6<=$G10),"."," ") | BJ10: =IF(AND(BJ$6>=$F10,BJ$6<=$G10),"."," ") | BK10: =IF(AND(BK$6>=$F10,BK$6<=$G10),"."," ") | BL10: =IF(AND(BL$6>=$F10,BL$6<=$G10),"."," ") | BM10: =IF(AND(BM$6>=$F10,BM$6<=$G10),"."," ") | BN10: =IF(AND(BN$6>=$F10,BN$6<=$G10),"."," ") | BQ10: =IF(AND(BQ$6>=$F10,BQ$6<=$G10),"."," ") | BR10: =IF(AND(BR$6>=$F10,BR$6<=$G10),"."," ") | BS10: =IF(AND(BS$6>=$F10,BS$6<=$G10),"."," ") | BT10: =IF(AND(BT$6>=$F10,BT$6<=$G10),"."," ") | BU10: =IF(AND(BU$6>=$F10,BU$6<=$G10),"."," ") | BX10: =IF(AND(BX$6>=$F10,BX$6<=$G10),"."," ") | BY10: =IF(AND(BY$6>=$F10,BY$6<=$G10),"."," ") | BZ10: =IF(AND(BZ$6>=$F10,BZ$6<=$G10),"."," ") | CA10: =IF(AND(CA$6>=$F10,CA$6<=$G10),"."," ") | CB10: =IF(AND(CB$6>=$F10,CB$6<=$G10),"."," ") | CE10: =IF(AND(CE$6>=$F10,CE$6<=$G10),"."," ") | CF10: =IF(AND(CF$6>=$F10,CF$6<=$G10),"."," ") | CG10: =IF(AND(CG$6>=$F10,CG$6<=$G10),"."," ") | CH10: =IF(AND(CH$6>=$F10,CH$6<=$G10),"."," ") | CI10: =IF(AND(CI$6>=$F10,CI$6<=$G10),"."," ") | CL10: =IF(AND(CL$6>=$F10,CL$6<=$G10),"."," ") | CM10: =IF(AND(CM$6>=$F10,CM$6<=$G10),"."," ") | CN10: =IF(AND(CN$6>=$F10,CN$6<=$G10),"."," ") | CO10: =IF(AND(CO$6>=$F10,CO$6<=$G10),"."," ") | CP10: =IF(AND(CP$6>=$F10,CP$6<=$G10),"."," ") | CS10: =IF(AND(CS$6>=$F10,CS$6<=$G10),"."," ") | CT10: =IF(AND(CT$6>=$F10,CT$6<=$G10),"."," ") | CU10: =IF(AND(CU$6>=$F10,CU$6<=$G10),"."," ") | CV10: =IF(AND(CV$6>=$F10,CV$6<=$G10),"."," ") | CW10: =IF(AND(CW$6>=$F10,CW$6<=$G10),"."," ") | CZ10: =IF(AND(CZ$6>=$F10,CZ$6<=$G10),"."," ") | DA10: =IF(AND(DA$6>=$F10,DA$6<=$G10),"."," ") | DB10: =IF(AND(DB$6>=$F10,DB$6<=$G10),"."," ") | DC10: =IF(AND(DC$6>=$F10,DC$6<=$G10),"."," ") | DD10: =IF(AND(DD$6>=$F10,DD$6<=$G10),"."," ") | DG10: =IF(AND(DG$6>=$F10,DG$6<=$G10),"."," ") | DH10: =IF(AND(DH$6>=$F10,DH$6<=$G10),"."," ") | DI10: =IF(AND(DI$6>=$F10,DI$6<=$G10),"."," ") | DJ10: =IF(AND(DJ$6>=$F10,DJ$6<=$G10),"."," ") | DK10: =IF(AND(DK$6>=$F10,DK$6<=$G10),"."," ") | DN10: =IF(AND(DN$6>=$F10,DN$6<=$G10),"."," ") | DO10: =IF(AND(DO$6>=$F10,DO$6<=$G10),"."," ") | DP10: =IF(AND(DP$6>=$F10,DP$6<=$G10),"."," ") | DQ10: =IF(AND(DQ$6>=$F10,DQ$6<=$G10),"."," ") | DR10: =IF(AND(DR$6>=$F10,DR$6<=$G10),"."," ") | DU10: =IF(AND(DU$6>=$F10,DU$6<=$G10),"."," ") | DV10: =IF(AND(DV$6>=$F10,DV$6<=$G10),"."," ") | DW10: =IF(AND(DW$6>=$F10,DW$6<=$G10),"."," ") | DX10: =IF(AND(DX$6>=$F10,DX$6<=$G10),"."," ") | DY10: =IF(AND(DY$6>=$F10,DY$6<=$G10),"."," ") | EB10: =IF(AND(EB$6>=$F10,EB$6<=$G10),"."," ") | EC10: =IF(AND(EC$6>=$F10,EC$6<=$G10),"."," ") | ED10: =IF(AND(ED$6>=$F10,ED$6<=$G10),"."," ") | EE10: =IF(AND(EE$6>=$F10,EE$6<=$G10),"."," ") | EF10: =IF(AND(EF$6>=$F10,EF$6<=$G10),"."," ") | EI10: =IF(AND(EI$6>=$F10,EI$6<=$G10),"."," ") | EJ10: =IF(AND(EJ$6>=$F10,EJ$6<=$G10),"."," ") | EK10: =IF(AND(EK$6>=$F10,EK$6<=$G10),"."," ") | EL10: =IF(AND(EL$6>=$F10,EL$6<=$G10),"."," ") | EM10: =IF(AND(EM$6>=$F10,EM$6<=$G10),"."," ") | EP10: =IF(AND(EP$6>=$F10,EP$6<=$G10),"."," ") | EQ10: =IF(AND(EQ$6>=$F10,EQ$6<=$G10),"."," ") | ER10: =IF(AND(ER$6>=$F10,ER$6<=$G10),"."," ") | ES10: =IF(AND(ES$6>=$F10,ES$6<=$G10),"."," ") | ET10: =IF(AND(ET$6>=$F10,ET$6<=$G10),"."," ") | EW10: =IF(AND(EW$6>=$F10,EW$6<=$G10),"."," ") | EX10: =IF(AND(EX$6>=$F10,EX$6<=$G10),"."," ") | EY10: =IF(AND(EY$6>=$F10,EY$6<=$G10),"."," ") | EZ10: =IF(AND(EZ$6>=$F10,EZ$6<=$G10),"."," ") | FA10: =IF(AND(FA$6>=$F10,FA$6<=$G10),"."," ") | FD10: =IF(AND(FD$6>=$F10,FD$6<=$G10),"."," ") | FE10: =IF(AND(FE$6>=$F10,FE$6<=$G10),"."," ") | FF10: =IF(AND(FF$6>=$F10,FF$6<=$G10),"."," ") | FG10: =IF(AND(FG$6>=$F10,FG$6<=$G10),"."," ") | FH10: =IF(AND(FH$6>=$F10,FH$6<=$G10),"."," ") | FK10: =IF(AND(FK$6>=$F10,FK$6<=$G10),"."," ") | FL10: =IF(AND(FL$6>=$F10,FL$6<=$G10),"."," ") | FM10: =IF(AND(FM$6>=$F10,FM$6<=$G10),"."," ") | FN10: =IF(AND(FN$6>=$F10,FN$6<=$G10),"."," ") | FO10: =IF(AND(FO$6>=$F10,FO$6<=$G10),"."," ") | FR10: =IF(AND(FR$6>=$F10,FR$6<=$G10),"."," ") | FS10: =IF(AND(FS$6>=$F10,FS$6<=$G10),"."," ") | FT10: =IF(AND(FT$6>=$F10,FT$6<=$G10),"."," ") | FU10: =IF(AND(FU$6>=$F10,FU$6<=$G10),"."," ") | FV10: =IF(AND(FV$6>=$F10,FV$6<=$G10),"."," ") | FY10: =IF(AND(FY$6>=$F10,FY$6<=$G10),"."," ") | FZ10: =IF(AND(FZ$6>=$F10,FZ$6<=$G10),"."," ") | GA10: =IF(AND(GA$6>=$F10,GA$6<=$G10),"."," ") | GB10: =IF(AND(GB$6>=$F10,GB$6<=$G10),"."," ") | GC10: =IF(AND(GC$6>=$F10,GC$6<=$G10),"."," ") | GF10: =IF(AND(GF$6>=$F10,GF$6<=$G10),"."," ") | GG10: =IF(AND(GG$6>=$F10,GG$6<=$G10),"."," ") | GH10: =IF(AND(GH$6>=$F10,GH$6<=$G10),"."," ") | GI10: =IF(AND(GI$6>=$F10,GI$6<=$G10),"."," ") | GJ10: =IF(AND(GJ$6>=$F10,GJ$6<=$G10),"."," ") | GM10: =IF(AND(GM$6>=$F10,GM$6<=$G10),"."," ") | GN10: =IF(AND(GN$6>=$F10,GN$6<=$G10),"."," ") | GO10: =IF(AND(GO$6>=$F10,GO$6<=$G10),"."," ") | GP10: =IF(AND(GP$6>=$F10,GP$6<=$G10),"."," ") | GQ10: =IF(AND(GQ$6>=$F10,GQ$6<=$G10),"."," ") | GT10: =IF(AND(GT$6>=$F10,GT$6<=$G10),"."," ") | GU10: =IF(AND(GU$6>=$F10,GU$6<=$G10),"."," ") | GV10: =IF(AND(GV$6>=$F10,GV$6<=$G10),"."," ") | GW10: =IF(AND(GW$6>=$F10,GW$6<=$G10),"."," ") | GX10: =IF(AND(GX$6>=$F10,GX$6<=$G10),"."," ") | HA10: =IF(AND(HA$6>=$F10,HA$6<=$G10),"."," ") | HB10: =IF(AND(HB$6>=$F10,HB$6<=$G10),"."," ") | HC10: =IF(AND(HC$6>=$F10,HC$6<=$G10),"."," ") | HD10: =IF(AND(HD$6>=$F10,HD$6<=$G10),"."," ") | HE10: =IF(AND(HE$6>=$F10,HE$6<=$G10),"."," ") | HH10: =IF(AND(HH$6>=$F10,HH$6<=$G10),"."," ") | HI10: =IF(AND(HI$6>=$F10,HI$6<=$G10),"."," ") | HJ10: =IF(AND(HJ$6>=$F10,HJ$6<=$G10),"."," ") | HK10: =IF(AND(HK$6>=$F10,HK$6<=$G10),"."," ") | HL10: =IF(AND(HL$6>=$F10,HL$6<=$G10),"."," ") | HO10: =IF(AND(HO$6>=$F10,HO$6<=$G10),"."," ") | HP10: =IF(AND(HP$6>=$F10,HP$6<=$G10),"."," ") | HQ10: =IF(AND(HQ$6>=$F10,HQ$6<=$G10),"."," ") | HR10: =IF(AND(HR$6>=$F10,HR$6<=$G10),"."," ") | HS10: =IF(AND(HS$6>=$F10,HS$6<=$G10),"."," ") | HV10: =IF(AND(HV$6>=$F10,HV$6<=$G10),"."," ") | HW10: =IF(AND(HW$6>=$F10,HW$6<=$G10),"."," ") | HX10: =IF(AND(HX$6>=$F10,HX$6<=$G10),"."," ") | HY10: =IF(AND(HY$6>=$F10,HY$6<=$G10),"."," ") | HZ10: =IF(AND(HZ$6>=$F10,HZ$6<=$G10),"."," ") | IC10: =IF(AND(IC$6>=$F10,IC$6<=$G10),"."," ") | ID10: =IF(AND(ID$6>=$F10,ID$6<=$G10),"."," ") | IE10: =IF(AND(IE$6>=$F10,IE$6<=$G10),"."," ") | IF10: =IF(AND(IF$6>=$F10,IF$6<=$G10),"."," ") | IG10: =IF(AND(IG$6>=$F10,IG$6<=$G10),"."," ") | IJ10: =IF(AND(IJ$6>=$F10,IJ$6<=$G10),"."," ") | IK10: =IF(AND(IK$6>=$F10,IK$6<=$G10),"."," ") | IL10: =IF(AND(IL$6>=$F10,IL$6<=$G10),"."," ") | IM10: =IF(AND(IM$6>=$F10,IM$6<=$G10),"."," ") | IN10: =IF(AND(IN$6>=$F10,IN$6<=$G10),"."," ") | IQ10: =IF(AND(IQ$6>=$F10,IQ$6<=$G10),"."," ") | IR10: =IF(AND(IR$6>=$F10,IR$6<=$G10),"."," ") | IS10: =IF(AND(IS$6>=$F10,IS$6<=$G10),"."," ") | IT10: =IF(AND(IT$6>=$F10,IT$6<=$G10),"."," ") | IU10: =IF(AND(IU$6>=$F10,IU$6<=$G10),"."," ") | IX10: =IF(AND(IX$6>=$F10,IX$6<=$G10),"."," ") | IY10: =IF(AND(IY$6>=$F10,IY$6<=$G10),"."," ") | IZ10: =IF(AND(IZ$6>=$F10,IZ$6<=$G10),"."," ") | JA10: =IF(AND(JA$6>=$F10,JA$6<=$G10),"."," ") | JB10: =IF(AND(JB$6>=$F10,JB$6<=$G10),"."," ") | JE10: =IF(AND(JE$6>=$F10,JE$6<=$G10),"."," ") | JF10: =IF(AND(JF$6>=$F10,JF$6<=$G10),"."," ") | JG10: =IF(AND(JG$6>=$F10,JG$6<=$G10),"."," ") | JH10: =IF(AND(JH$6>=$F10,JH$6<=$G10),"."," ") | JI10: =IF(AND(JI$6>=$F10,JI$6<=$G10),"."," ")
B11: =B10+1 -> 3 | C11: Sign Off Business Requirements | D11: John | E11: 2 | F11: =VLOOKUP(E11,$B$6:$G$150,6,FALSE) + 1 -> 42507 | G11: =WORKDAY(F11,H11-1,Config!D9:D28) -> 42507 | H11: 1 | I11: 1 | J11: =IF(((NETWORKDAYS(F11,TODAY(),Data!C4:C23)*100)/H11)/100 > 0,((NETWORKDAYS(F11,TODAY(),Data!C4:C23)*100)/H11)/100,0) -> 1664 | K11: =IF(J11>1, "100%",$J11) -> 100% | L11: =K11-I11 -> 0 | M11: =IF(AND(M$6>=$F11,M$6<=$G11),"."," ") | N11: =IF(AND(N$6>=$F11,N$6<=$G11),"."," ") | O11: =IF(AND(O$6>=$F11,O$6<=$G11),"."," ") | P11: =IF(AND(P$6>=$F11,P$6<=$G11),"."," ") | Q11: =IF(AND(Q$6>=$F11,Q$6<=$G11),"."," ") | T11: =IF(AND(T$6>=$F11,T$6<=$G11),"."," ") | U11: =IF(AND(U$6>=$F11,U$6<=$G11),"."," ") | V11: =IF(AND(V$6>=$F11,V$6<=$G11),"."," ") | W11: =IF(AND(W$6>=$F11,W$6<=$G11),"."," ") | X11: =IF(AND(X$6>=$F11,X$6<=$G11),"."," ") | AA11: =IF(AND(AA$6>=$F11,AA$6<=$G11),"."," ") | AB11: =IF(AND(AB$6>=$F11,AB$6<=$G11),"."," ") | AC11: =IF(AND(AC$6>=$F11,AC$6<=$G11),"."," ") | AD11: =IF(AND(AD$6>=$F11,AD$6<=$G11),"."," ") | AE11: =IF(AND(AE$6>=$F11,AE$6<=$G11),"."," ") | AH11: =IF(AND(AH$6>=$F11,AH$6<=$G11),"."," ") | AI11: =IF(AND(AI$6>=$F11,AI$6<=$G11),"."," ") | AJ11: =IF(AND(AJ$6>=$F11,AJ$6<=$G11),"."," ") | AK11: =IF(AND(AK$6>=$F11,AK$6<=$G11),"."," ") | AL11: =IF(AND(AL$6>=$F11,AL$6<=$G11),"."," ") | AO11: =IF(AND(AO$6>=$F11,AO$6<=$G11),"."," ") | AP11: =IF(AND(AP$6>=$F11,AP$6<=$G11),"."," ") | AQ11: =IF(AND(AQ$6>=$F11,AQ$6<=$G11),"."," ") | AR11: =IF(AND(AR$6>=$F11,AR$6<=$G11),"."," ") | AS11: =IF(AND(AS$6>=$F11,AS$6<=$G11),"."," ") | AV11: =IF(AND(AV$6>=$F11,AV$6<=$G11),"."," ") | AW11: =IF(AND(AW$6>=$F11,AW$6<=$G11),"."," ") | AX11: =IF(AND(AX$6>=$F11,AX$6<=$G11),"."," ") | AY11: =IF(AND(AY$6>=$F11,AY$6<=$G11),"."," ") | AZ11: =IF(AND(AZ$6>=$F11,AZ$6<=$G11),"."," ") | BC11: =IF(AND(BC$6>=$F11,BC$6<=$G11),"."," ") | BD11: =IF(AND(BD$6>=$F11,BD$6<=$G11),"."," ") | BE11: =IF(AND(BE$6>=$F11,BE$6<=$G11),"."," ") | BF11: =IF(AND(BF$6>=$F11,BF$6<=$G11),"."," ") | BG11: =IF(AND(BG$6>=$F11,BG$6<=$G11),"."," ") | BJ11: =IF(AND(BJ$6>=$F11,BJ$6<=$G11),"."," ") | BK11: =IF(AND(BK$6>=$F11,BK$6<=$G11),"."," ") | BL11: =IF(AND(BL$6>=$F11,BL$6<=$G11),"."," ") | BM11: =IF(AND(BM$6>=$F11,BM$6<=$G11),"."," ") | BN11: =IF(AND(BN$6>=$F11,BN$6<=$G11),"."," ") | BQ11: =IF(AND(BQ$6>=$F11,BQ$6<=$G11),"."," ") | BR11: =IF(AND(BR$6>=$F11,BR$6<=$G11),"."," ") | BS11: =IF(AND(BS$6>=$F11,BS$6<=$G11),"."," ") | BT11: =IF(AND(BT$6>=$F11,BT$6<=$G11),"."," ") | BU11: =IF(AND(BU$6>=$F11,BU$6<=$G11),"."," ") | BX11: =IF(AND(BX$6>=$F11,BX$6<=$G11),"."," ") | BY11: =IF(AND(BY$6>=$F11,BY$6<=$G11),"."," ") | BZ11: =IF(AND(BZ$6>=$F11,BZ$6<=$G11),"."," ") | CA11: =IF(AND(CA$6>=$F11,CA$6<=$G11),"."," ") | CB11: =IF(AND(CB$6>=$F11,CB$6<=$G11),"."," ") | CE11: =IF(AND(CE$6>=$F11,CE$6<=$G11),"."," ") | CF11: =IF(AND(CF$6>=$F11,CF$6<=$G11),"."," ") | CG11: =IF(AND(CG$6>=$F11,CG$6<=$G11),"."," ") | CH11: =IF(AND(CH$6>=$F11,CH$6<=$G11),"."," ") | CI11: =IF(AND(CI$6>=$F11,CI$6<=$G11),"."," ") | CL11: =IF(AND(CL$6>=$F11,CL$6<=$G11),"."," ") | CM11: =IF(AND(CM$6>=$F11,CM$6<=$G11),"."," ") | CN11: =IF(AND(CN$6>=$F11,CN$6<=$G11),"."," ") | CO11: =IF(AND(CO$6>=$F11,CO$6<=$G11),"."," ") | CP11: =IF(AND(CP$6>=$F11,CP$6<=$G11),"."," ") | CS11: =IF(AND(CS$6>=$F11,CS$6<=$G11),"."," ") | CT11: =IF(AND(CT$6>=$F11,CT$6<=$G11),"."," ") | CU11: =IF(AND(CU$6>=$F11,CU$6<=$G11),"."," ") | CV11: =IF(AND(CV$6>=$F11,CV$6<=$G11),"."," ") | CW11: =IF(AND(CW$6>=$F11,CW$6<=$G11),"."," ") | CZ11: =IF(AND(CZ$6>=$F11,CZ$6<=$G11),"."," ") | DA11: =IF(AND(DA$6>=$F11,DA$6<=$G11),"."," ") | DB11: =IF(AND(DB$6>=$F11,DB$6<=$G11),"."," ") | DC11: =IF(AND(DC$6>=$F11,DC$6<=$G11),"."," ") | DD11: =IF(AND(DD$6>=$F11,DD$6<=$G11),"."," ") | DG11: =IF(AND(DG$6>=$F11,DG$6<=$G11),"."," ") | DH11: =IF(AND(DH$6>=$F11,DH$6<=$G11),"."," ") | DI11: =IF(AND(DI$6>=$F11,DI$6<=$G11),"."," ") | DJ11: =IF(AND(DJ$6>=$F11,DJ$6<=$G11),"."," ") | DK11: =IF(AND(DK$6>=$F11,DK$6<=$G11),"."," ") | DN11: =IF(AND(DN$6>=$F11,DN$6<=$G11),"."," ") | DO11: =IF(AND(DO$6>=$F11,DO$6<=$G11),"."," ") | DP11: =IF(AND(DP$6>=$F11,DP$6<=$G11),"."," ") | DQ11: =IF(AND(DQ$6>=$F11,DQ$6<=$G11),"."," ") | DR11: =IF(AND(DR$6>=$F11,DR$6<=$G11),"."," ") | DU11: =IF(AND(DU$6>=$F11,DU$6<=$G11),"."," ") | DV11: =IF(AND(DV$6>=$F11,DV$6<=$G11),"."," ") | DW11: =IF(AND(DW$6>=$F11,DW$6<=$G11),"."," ") | DX11: =IF(AND(DX$6>=$F11,DX$6<=$G11),"."," ") | DY11: =IF(AND(DY$6>=$F11,DY$6<=$G11),"."," ") | EB11: =IF(AND(EB$6>=$F11,EB$6<=$G11),"."," ") | EC11: =IF(AND(EC$6>=$F11,EC$6<=$G11),"."," ") | ED11: =IF(AND(ED$6>=$F11,ED$6<=$G11),"."," ") | EE11: =IF(AND(EE$6>=$F11,EE$6<=$G11),"."," ") | EF11: =IF(AND(EF$6>=$F11,EF$6<=$G11),"."," ") | EI11: =IF(AND(EI$6>=$F11,EI$6<=$G11),"."," ") | EJ11: =IF(AND(EJ$6>=$F11,EJ$6<=$G11),"."," ") | EK11: =IF(AND(EK$6>=$F11,EK$6<=$G11),"."," ") | EL11: =IF(AND(EL$6>=$F11,EL$6<=$G11),"."," ") | EM11: =IF(AND(EM$6>=$F11,EM$6<=$G11),"."," ") | EP11: =IF(AND(EP$6>=$F11,EP$6<=$G11),"."," ") | EQ11: =IF(AND(EQ$6>=$F11,EQ$6<=$G11),"."," ") | ER11: =IF(AND(ER$6>=$F11,ER$6<=$G11),"."," ") | ES11: =IF(AND(ES$6>=$F11,ES$6<=$G11),"."," ") | ET11: =IF(AND(ET$6>=$F11,ET$6<=$G11),"."," ") | EW11: =IF(AND(EW$6>=$F11,EW$6<=$G11),"."," ") | EX11: =IF(AND(EX$6>=$F11,EX$6<=$G11),"."," ") | EY11: =IF(AND(EY$6>=$F11,EY$6<=$G11),"."," ") | EZ11: =IF(AND(EZ$6>=$F11,EZ$6<=$G11),"."," ") | FA11: =IF(AND(FA$6>=$F11,FA$6<=$G11),"."," ") | FD11: =IF(AND(FD$6>=$F11,FD$6<=$G11),"."," ") | FE11: =IF(AND(FE$6>=$F11,FE$6<=$G11),"."," ") | FF11: =IF(AND(FF$6>=$F11,FF$6<=$G11),"."," ") | FG11: =IF(AND(FG$6>=$F11,FG$6<=$G11),"."," ") | FH11: =IF(AND(FH$6>=$F11,FH$6<=$G11),"."," ") | FK11: =IF(AND(FK$6>=$F11,FK$6<=$G11),"."," ") | FL11: =IF(AND(FL$6>=$F11,FL$6<=$G11),"."," ") | FM11: =IF(AND(FM$6>=$F11,FM$6<=$G11),"."," ") | FN11: =IF(AND(FN$6>=$F11,FN$6<=$G11),"."," ") | FO11: =IF(AND(FO$6>=$F11,FO$6<=$G11),"."," ") | FR11: =IF(AND(FR$6>=$F11,FR$6<=$G11),"."," ") | FS11: =IF(AND(FS$6>=$F11,FS$6<=$G11),"."," ") | FT11: =IF(AND(FT$6>=$F11,FT$6<=$G11),"."," ") | FU11: =IF(AND(FU$6>=$F11,FU$6<=$G11),"."," ") | FV11: =IF(AND(FV$6>=$F11,FV$6<=$G11),"."," ") | FY11: =IF(AND(FY$6>=$F11,FY$6<=$G11),"."," ") | FZ11: =IF(AND(FZ$6>=$F11,FZ$6<=$G11),"."," ") | GA11: =IF(AND(GA$6>=$F11,GA$6<=$G11),"."," ") | GB11: =IF(AND(GB$6>=$F11,GB$6<=$G11),"."," ") | GC11: =IF(AND(GC$6>=$F11,GC$6<=$G11),"."," ") | GF11: =IF(AND(GF$6>=$F11,GF$6<=$G11),"."," ") | GG11: =IF(AND(GG$6>=$F11,GG$6<=$G11),"."," ") | GH11: =IF(AND(GH$6>=$F11,GH$6<=$G11),"."," ") | GI11: =IF(AND(GI$6>=$F11,GI$6<=$G11),"."," ") | GJ11: =IF(AND(GJ$6>=$F11,GJ$6<=$G11),"."," ") | GM11: =IF(AND(GM$6>=$F11,GM$6<=$G11),"."," ") | GN11: =IF(AND(GN$6>=$F11,GN$6<=$G11),"."," ") | GO11: =IF(AND(GO$6>=$F11,GO$6<=$G11),"."," ") | GP11: =IF(AND(GP$6>=$F11,GP$6<=$G11),"."," ") | GQ11: =IF(AND(GQ$6>=$F11,GQ$6<=$G11),"."," ") | GT11: =IF(AND(GT$6>=$F11,GT$6<=$G11),"."," ") | GU11: =IF(AND(GU$6>=$F11,GU$6<=$G11),"."," ") | GV11: =IF(AND(GV$6>=$F11,GV$6<=$G11),"."," ") | GW11: =IF(AND(GW$6>=$F11,GW$6<=$G11),"."," ") | GX11: =IF(AND(GX$6>=$F11,GX$6<=$G11),"."," ") | HA11: =IF(AND(HA$6>=$F11,HA$6<=$G11),"."," ") | HB11: =IF(AND(HB$6>=$F11,HB$6<=$G11),"."," ") | HC11: =IF(AND(HC$6>=$F11,HC$6<=$G11),"."," ") | HD11: =IF(AND(HD$6>=$F11,HD$6<=$G11),"."," ") | HE11: =IF(AND(HE$6>=$F11,HE$6<=$G11),"."," ") | HH11: =IF(AND(HH$6>=$F11,HH$6<=$G11),"."," ") | HI11: =IF(AND(HI$6>=$F11,HI$6<=$G11),"."," ") | HJ11: =IF(AND(HJ$6>=$F11,HJ$6<=$G11),"."," ") | HK11: =IF(AND(HK$6>=$F11,HK$6<=$G11),"."," ") | HL11: =IF(AND(HL$6>=$F11,HL$6<=$G11),"."," ") | HO11: =IF(AND(HO$6>=$F11,HO$6<=$G11),"."," ") | HP11: =IF(AND(HP$6>=$F11,HP$6<=$G11),"."," ") | HQ11: =IF(AND(HQ$6>=$F11,HQ$6<=$G11),"."," ") | HR11: =IF(AND(HR$6>=$F11,HR$6<=$G11),"."," ") | HS11: =IF(AND(HS$6>=$F11,HS$6<=$G11),"."," ") | HV11: =IF(AND(HV$6>=$F11,HV$6<=$G11),"."," ") | HW11: =IF(AND(HW$6>=$F11,HW$6<=$G11),"."," ") | HX11: =IF(AND(HX$6>=$F11,HX$6<=$G11),"."," ") | HY11: =IF(AND(HY$6>=$F11,HY$6<=$G11),"."," ") | HZ11: =IF(AND(HZ$6>=$F11,HZ$6<=$G11),"."," ") | IC11: =IF(AND(IC$6>=$F11,IC$6<=$G11),"."," ") | ID11: =IF(AND(ID$6>=$F11,ID$6<=$G11),"."," ") | IE11: =IF(AND(IE$6>=$F11,IE$6<=$G11),"."," ") | IF11: =IF(AND(IF$6>=$F11,IF$6<=$G11),"."," ") | IG11: =IF(AND(IG$6>=$F11,IG$6<=$G11),"."," ") | IJ11: =IF(AND(IJ$6>=$F11,IJ$6<=$G11),"."," ") | IK11: =IF(AND(IK$6>=$F11,IK$6<=$G11),"."," ") | IL11: =IF(AND(IL$6>=$F11,IL$6<=$G11),"."," ") | IM11: =IF(AND(IM$6>=$F11,IM$6<=$G11),"."," ") | IN11: =IF(AND(IN$6>=$F11,IN$6<=$G11),"."," ") | IQ11: =IF(AND(IQ$6>=$F11,IQ$6<=$G11),"."," ") | IR11: =IF(AND(IR$6>=$F11,IR$6<=$G11),"."," ") | IS11: =IF(AND(IS$6>=$F11,IS$6<=$G11),"."," ") | IT11: =IF(AND(IT$6>=$F11,IT$6<=$G11),"."," ") | IU11: =IF(AND(IU$6>=$F11,IU$6<=$G11),"."," ") | IX11: =IF(AND(IX$6>=$F11,IX$6<=$G11),"."," ") | IY11: =IF(AND(IY$6>=$F11,IY$6<=$G11),"."," ") | IZ11: =IF(AND(IZ$6>=$F11,IZ$6<=$G11),"."," ") | JA11: =IF(AND(JA$6>=$F11,JA$6<=$G11),"."," ") | JB11: =IF(AND(JB$6>=$F11,JB$6<=$G11),"."," ") | JE11: =IF(AND(JE$6>=$F11,JE$6<=$G11),"."," ") | JF11: =IF(AND(JF$6>=$F11,JF$6<=$G11),"."," ") | JG11: =IF(AND(JG$6>=$F11,JG$6<=$G11),"."," ") | JH11: =IF(AND(JH$6>=$F11,JH$6<=$G11),"."," ") | JI11: =IF(AND(JI$6>=$F11,JI$6<=$G11),"."," ")
B12: =B11+1 -> 4 | C12: Draft Functional Requirements | D12: John | E12: 3 | F12: =VLOOKUP(E12,$B$6:$G$150,6,FALSE) + 1 -> 42508 | G12: =WORKDAY(F12,H12-1,Config!D10:D29) -> 42509 | H12: 2 | I12: 1 | J12: =IF(((NETWORKDAYS(F12,TODAY(),Data!C5:C24)*100)/H12)/100 > 0,((NETWORKDAYS(F12,TODAY(),Data!C5:C24)*100)/H12)/100,0) -> 831.5 | K12: =IF(J12>1, "100%",$J12) -> 100% | L12: =K12-I12 -> 0 | M12: =IF(AND(M$6>=$F12,M$6<=$G12),"."," ") | N12: =IF(AND(N$6>=$F12,N$6<=$G12),"."," ") | O12: =IF(AND(O$6>=$F12,O$6<=$G12),"."," ") | P12: =IF(AND(P$6>=$F12,P$6<=$G12),"."," ") | Q12: =IF(AND(Q$6>=$F12,Q$6<=$G12),"."," ") | T12: =IF(AND(T$6>=$F12,T$6<=$G12),"."," ") | U12: =IF(AND(U$6>=$F12,U$6<=$G12),"."," ") | V12: =IF(AND(V$6>=$F12,V$6<=$G12),"."," ") | W12: =IF(AND(W$6>=$F12,W$6<=$G12),"."," ") | X12: =IF(AND(X$6>=$F12,X$6<=$G12),"."," ") | AA12: =IF(AND(AA$6>=$F12,AA$6<=$G12),"."," ") -> . | AB12: =IF(AND(AB$6>=$F12,AB$6<=$G12),"."," ") | AC12: =IF(AND(AC$6>=$F12,AC$6<=$G12),"."," ") | AD12: =IF(AND(AD$6>=$F12,AD$6<=$G12),"."," ") | AE12: =IF(AND(AE$6>=$F12,AE$6<=$G12),"."," ") | AH12: =IF(AND(AH$6>=$F12,AH$6<=$G12),"."," ") | AI12: =IF(AND(AI$6>=$F12,AI$6<=$G12),"."," ") | AJ12: =IF(AND(AJ$6>=$F12,AJ$6<=$G12),"."," ") | AK12: =IF(AND(AK$6>=$F12,AK$6<=$G12),"."," ") | AL12: =IF(AND(AL$6>=$F12,AL$6<=$G12),"."," ") | AO12: =IF(AND(AO$6>=$F12,AO$6<=$G12),"."," ") | AP12: =IF(AND(AP$6>=$F12,AP$6<=$G12),"."," ") | AQ12: =IF(AND(AQ$6>=$F12,AQ$6<=$G12),"."," ") | AR12: =IF(AND(AR$6>=$F12,AR$6<=$G12),"."," ") | AS12: =IF(AND(AS$6>=$F12,AS$6<=$G12),"."," ") | AV12: =IF(AND(AV$6>=$F12,AV$6<=$G12),"."," ") | AW12: =IF(AND(AW$6>=$F12,AW$6<=$G12),"."," ") | AX12: =IF(AND(AX$6>=$F12,AX$6<=$G12),"."," ") | AY12: =IF(AND(AY$6>=$F12,AY$6<=$G12),"."," ") | AZ12: =IF(AND(AZ$6>=$F12,AZ$6<=$G12),"."," ") | BC12: =IF(AND(BC$6>=$F12,BC$6<=$G12),"."," ") | BD12: =IF(AND(BD$6>=$F12,BD$6<=$G12),"."," ") | BE12: =IF(AND(BE$6>=$F12,BE$6<=$G12),"."," ") | BF12: =IF(AND(BF$6>=$F12,BF$6<=$G12),"."," ") | BG12: =IF(AND(BG$6>=$F12,BG$6<=$G12),"."," ") | BJ12: =IF(AND(BJ$6>=$F12,BJ$6<=$G12),"."," ") | BK12: =IF(AND(BK$6>=$F12,BK$6<=$G12),"."," ") | BL12: =IF(AND(BL$6>=$F12,BL$6<=$G12),"."," ") | BM12: =IF(AND(BM$6>=$F12,BM$6<=$G12),"."," ") | BN12: =IF(AND(BN$6>=$F12,BN$6<=$G12),"."," ") | BQ12: =IF(AND(BQ$6>=$F12,BQ$6<=$G12),"."," ") | BR12: =IF(AND(BR$6>=$F12,BR$6<=$G12),"."," ") | BS12: =IF(AND(BS$6>=$F12,BS$6<=$G12),"."," ") | BT12: =IF(AND(BT$6>=$F12,BT$6<=$G12),"."," ") | BU12: =IF(AND(BU$6>=$F12,BU$6<=$G12),"."," ") | BX12: =IF(AND(BX$6>=$F12,BX$6<=$G12),"."," ") | BY12: =IF(AND(BY$6>=$F12,BY$6<=$G12),"."," ") | BZ12: =IF(AND(BZ$6>=$F12,BZ$6<=$G12),"."," ") | CA12: =IF(AND(CA$6>=$F12,CA$6<=$G12),"."," ") | CB12: =IF(AND(CB$6>=$F12,CB$6<=$G12),"."," ") | CE12: =IF(AND(CE$6>=$F12,CE$6<=$G12),"."," ") | CF12: =IF(AND(CF$6>=$F12,CF$6<=$G12),"."," ") | CG12: =IF(AND(CG$6>=$F12,CG$6<=$G12),"."," ") | CH12: =IF(AND(CH$6>=$F12,CH$6<=$G12),"."," ") | CI12: =IF(AND(CI$6>=$F12,CI$6<=$G12),"."," ") | CL12: =IF(AND(CL$6>=$F12,CL$6<=$G12),"."," ") | CM12: =IF(AND(CM$6>=$F12,CM$6<=$G12),"."," ") | CN12: =IF(AND(CN$6>=$F12,CN$6<=$G12),"."," ") | CO12: =IF(AND(CO$6>=$F12,CO$6<=$G12),"."," ") | CP12: =IF(AND(CP$6>=$F12,CP$6<=$G12),"."," ") | CS12: =IF(AND(CS$6>=$F12,CS$6<=$G12),"."," ") | CT12: =IF(AND(CT$6>=$F12,CT$6<=$G12),"."," ") | CU12: =IF(AND(CU$6>=$F12,CU$6<=$G12),"."," ") | CV12: =IF(AND(CV$6>=$F12,CV$6<=$G12),"."," ") | CW12: =IF(AND(CW$6>=$F12,CW$6<=$G12),"."," ") | CZ12: =IF(AND(CZ$6>=$F12,CZ$6<=$G12),"."," ") | DA12: =IF(AND(DA$6>=$F12,DA$6<=$G12),"."," ") | DB12: =IF(AND(DB$6>=$F12,DB$6<=$G12),"."," ") | DC12: =IF(AND(DC$6>=$F12,DC$6<=$G12),"."," ") | DD12: =IF(AND(DD$6>=$F12,DD$6<=$G12),"."," ") | DG12: =IF(AND(DG$6>=$F12,DG$6<=$G12),"."," ") | DH12: =IF(AND(DH$6>=$F12,DH$6<=$G12),"."," ") | DI12: =IF(AND(DI$6>=$F12,DI$6<=$G12),"."," ") | DJ12: =IF(AND(DJ$6>=$F12,DJ$6<=$G12),"."," ") | DK12: =IF(AND(DK$6>=$F12,DK$6<=$G12),"."," ") | DN12: =IF(AND(DN$6>=$F12,DN$6<=$G12),"."," ") | DO12: =IF(AND(DO$6>=$F12,DO$6<=$G12),"."," ") | DP12: =IF(AND(DP$6>=$F12,DP$6<=$G12),"."," ") | DQ12: =IF(AND(DQ$6>=$F12,DQ$6<=$G12),"."," ") | DR12: =IF(AND(DR$6>=$F12,DR$6<=$G12),"."," ") | DU12: =IF(AND(DU$6>=$F12,DU$6<=$G12),"."," ") | DV12: =IF(AND(DV$6>=$F12,DV$6<=$G12),"."," ") | DW12: =IF(AND(DW$6>=$F12,DW$6<=$G12),"."," ") | DX12: =IF(AND(DX$6>=$F12,DX$6<=$G12),"."," ") | DY12: =IF(AND(DY$6>=$F12,DY$6<=$G12),"."," ") | EB12: =IF(AND(EB$6>=$F12,EB$6<=$G12),"."," ") | EC12: =IF(AND(EC$6>=$F12,EC$6<=$G12),"."," ") | ED12: =IF(AND(ED$6>=$F12,ED$6<=$G12),"."," ") | EE12: =IF(AND(EE$6>=$F12,EE$6<=$G12),"."," ") | EF12: =IF(AND(EF$6>=$F12,EF$6<=$G12),"."," ") | EI12: =IF(AND(EI$6>=$F12,EI$6<=$G12),"."," ") | EJ12: =IF(AND(EJ$6>=$F12,EJ$6<=$G12),"."," ") | EK12: =IF(AND(EK$6>=$F12,EK$6<=$G12),"."," ") | EL12: =IF(AND(EL$6>=$F12,EL$6<=$G12),"."," ") | EM12: =IF(AND(EM$6>=$F12,EM$6<=$G12),"."," ") | EP12: =IF(AND(EP$6>=$F12,EP$6<=$G12),"."," ") | EQ12: =IF(AND(EQ$6>=$F12,EQ$6<=$G12),"."," ") | ER12: =IF(AND(ER$6>=$F12,ER$6<=$G12),"."," ") | ES12: =IF(AND(ES$6>=$F12,ES$6<=$G12),"."," ") | ET12: =IF(AND(ET$6>=$F12,ET$6<=$G12),"."," ") | EW12: =IF(AND(EW$6>=$F12,EW$6<=$G12),"."," ") | EX12: =IF(AND(EX$6>=$F12,EX$6<=$G12),"."," ") | EY12: =IF(AND(EY$6>=$F12,EY$6<=$G12),"."," ") | EZ12: =IF(AND(EZ$6>=$F12,EZ$6<=$G12),"."," ") | FA12: =IF(AND(FA$6>=$F12,FA$6<=$G12),"."," ") | FD12: =IF(AND(FD$6>=$F12,FD$6<=$G12),"."," ") | FE12: =IF(AND(FE$6>=$F12,FE$6<=$G12),"."," ") | FF12: =IF(AND(FF$6>=$F12,FF$6<=$G12),"."," ") | FG12: =IF(AND(FG$6>=$F12,FG$6<=$G12),"."," ") | FH12: =IF(AND(FH$6>=$F12,FH$6<=$G12),"."," ") | FK12: =IF(AND(FK$6>=$F12,FK$6<=$G12),"."," ") | FL12: =IF(AND(FL$6>=$F12,FL$6<=$G12),"."," ") | FM12: =IF(AND(FM$6>=$F12,FM$6<=$G12),"."," ") | FN12: =IF(AND(FN$6>=$F12,FN$6<=$G12),"."," ") | FO12: =IF(AND(FO$6>=$F12,FO$6<=$G12),"."," ") | FR12: =IF(AND(FR$6>=$F12,FR$6<=$G12),"."," ") | FS12: =IF(AND(FS$6>=$F12,FS$6<=$G12),"."," ") | FT12: =IF(AND(FT$6>=$F12,FT$6<=$G12),"."," ") | FU12: =IF(AND(FU$6>=$F12,FU$6<=$G12),"."," ") | FV12: =IF(AND(FV$6>=$F12,FV$6<=$G12),"."," ") | FY12: =IF(AND(FY$6>=$F12,FY$6<=$G12),"."," ") | FZ12: =IF(AND(FZ$6>=$F12,FZ$6<=$G12),"."," ") | GA12: =IF(AND(GA$6>=$F12,GA$6<=$G12),"."," ") | GB12: =IF(AND(GB$6>=$F12,GB$6<=$G12),"."," ") | GC12: =IF(AND(GC$6>=$F12,GC$6<=$G12),"."," ") | GF12: =IF(AND(GF$6>=$F12,GF$6<=$G12),"."," ") | GG12: =IF(AND(GG$6>=$F12,GG$6<=$G12),"."," ") | GH12: =IF(AND(GH$6>=$F12,GH$6<=$G12),"."," ") | GI12: =IF(AND(GI$6>=$F12,GI$6<=$G12),"."," ") | GJ12: =IF(AND(GJ$6>=$F12,GJ$6<=$G12),"."," ") | GM12: =IF(AND(GM$6>=$F12,GM$6<=$G12),"."," ") | GN12: =IF(AND(GN$6>=$F12,GN$6<=$G12),"."," ") | GO12: =IF(AND(GO$6>=$F12,GO$6<=$G12),"."," ") | GP12: =IF(AND(GP$6>=$F12,GP$6<=$G12),"."," ") | GQ12: =IF(AND(GQ$6>=$F12,GQ$6<=$G12),"."," ") | GT12: =IF(AND(GT$6>=$F12,GT$6<=$G12),"."," ") | GU12: =IF(AND(GU$6>=$F12,GU$6<=$G12),"."," ") | GV12: =IF(AND(GV$6>=$F12,GV$6<=$G12),"."," ") | GW12: =IF(AND(GW$6>=$F12,GW$6<=$G12),"."," ") | GX12: =IF(AND(GX$6>=$F12,GX$6<=$G12),"."," ") | HA12: =IF(AND(HA$6>=$F12,HA$6<=$G12),"."," ") | HB12: =IF(AND(HB$6>=$F12,HB$6<=$G12),"."," ") | HC12: =IF(AND(HC$6>=$F12,HC$6<=$G12),"."," ") | HD12: =IF(AND(HD$6>=$F12,HD$6<=$G12),"."," ") | HE12: =IF(AND(HE$6>=$F12,HE$6<=$G12),"."," ") | HH12: =IF(AND(HH$6>=$F12,HH$6<=$G12),"."," ") | HI12: =IF(AND(HI$6>=$F12,HI$6<=$G12),"."," ") | HJ12: =IF(AND(HJ$6>=$F12,HJ$6<=$G12),"."," ") | HK12: =IF(AND(HK$6>=$F12,HK$6<=$G12),"."," ") | HL12: =IF(AND(HL$6>=$F12,HL$6<=$G12),"."," ") | HO12: =IF(AND(HO$6>=$F12,HO$6<=$G12),"."," ") | HP12: =IF(AND(HP$6>=$F12,HP$6<=$G12),"."," ") | HQ12: =IF(AND(HQ$6>=$F12,HQ$6<=$G12),"."," ") | HR12: =IF(AND(HR$6>=$F12,HR$6<=$G12),"."," ") | HS12: =IF(AND(HS$6>=$F12,HS$6<=$G12),"."," ") | HV12: =IF(AND(HV$6>=$F12,HV$6<=$G12),"."," ") | HW12: =IF(AND(HW$6>=$F12,HW$6<=$G12),"."," ") | HX12: =IF(AND(HX$6>=$F12,HX$6<=$G12),"."," ") | HY12: =IF(AND(HY$6>=$F12,HY$6<=$G12),"."," ") | HZ12: =IF(AND(HZ$6>=$F12,HZ$6<=$G12),"."," ") | IC12: =IF(AND(IC$6>=$F12,IC$6<=$G12),"."," ") | ID12: =IF(AND(ID$6>=$F12,ID$6<=$G12),"."," ") | IE12: =IF(AND(IE$6>=$F12,IE$6<=$G12),"."," ") | IF12: =IF(AND(IF$6>=$F12,IF$6<=$G12),"."," ") | IG12: =IF(AND(IG$6>=$F12,IG$6<=$G12),"."," ") | IJ12: =IF(AND(IJ$6>=$F12,IJ$6<=$G12),"."," ") | IK12: =IF(AND(IK$6>=$F12,IK$6<=$G12),"."," ") | IL12: =IF(AND(IL$6>=$F12,IL$6<=$G12),"."," ") | IM12: =IF(AND(IM$6>=$F12,IM$6<=$G12),"."," ") | IN12: =IF(AND(IN$6>=$F12,IN$6<=$G12),"."," ") | IQ12: =IF(AND(IQ$6>=$F12,IQ$6<=$G12),"."," ") | IR12: =IF(AND(IR$6>=$F12,IR$6<=$G12),"."," ") | IS12: =IF(AND(IS$6>=$F12,IS$6<=$G12),"."," ") | IT12: =IF(AND(IT$6>=$F12,IT$6<=$G12),"."," ") | IU12: =IF(AND(IU$6>=$F12,IU$6<=$G12),"."," ") | IX12: =IF(AND(IX$6>=$F12,IX$6<=$G12),"."," ") | IY12: =IF(AND(IY$6>=$F12,IY$6<=$G12),"."," ") | IZ12: =IF(AND(IZ$6>=$F12,IZ$6<=$G12),"."," ") | JA12: =IF(AND(JA$6>=$F12,JA$6<=$G12),"."," ") | JB12: =IF(AND(JB$6>=$F12,JB$6<=$G12),"."," ") | JE12: =IF(AND(JE$6>=$F12,JE$6<=$G12),"."," ") | JF12: =IF(AND(JF$6>=$F12,JF$6<=$G12),"."," ") | JG12: =IF(AND(JG$6>=$F12,JG$6<=$G12),"."," ") | JH12: =IF(AND(JH$6>=$F12,JH$6<=$G12),"."," ") | JI12: =IF(AND(JI$6>=$F12,JI$6<=$G12),"."," ")
B13: =B12+1 -> 5 | C13: Sign Off Functional Requirements | D13: John | E13: 4 | F13: =VLOOKUP(E13,$B$6:$G$150,6,FALSE) + 1 -> 42510 | G13: =WORKDAY(F13,H13-1,Config!D11:D30) -> 42514 | H13: 3 | I13: 0.9 | J13: =IF(((NETWORKDAYS(F13,TODAY(),Data!C6:C25)*100)/H13)/100 > 0,((NETWORKDAYS(F13,TODAY(),Data!C6:C25)*100)/H13)/100,0) -> 553.66667 | K13: =IF(J13>1, "100%",$J13) -> 100% | L13: =K13-I13 -> 0.1 | M13: =IF(AND(M$6>=$F13,M$6<=$G13),"."," ") | N13: =IF(AND(N$6>=$F13,N$6<=$G13),"."," ") | O13: =IF(AND(O$6>=$F13,O$6<=$G13),"."," ") | P13: =IF(AND(P$6>=$F13,P$6<=$G13),"."," ") | Q13: =IF(AND(Q$6>=$F13,Q$6<=$G13),"."," ") | T13: =IF(AND(T$6>=$F13,T$6<=$G13),"."," ") | U13: =IF(AND(U$6>=$F13,U$6<=$G13),"."," ") | V13: =IF(AND(V$6>=$F13,V$6<=$G13),"."," ") | W13: =IF(AND(W$6>=$F13,W$6<=$G13),"."," ") | X13: =IF(AND(X$6>=$F13,X$6<=$G13),"."," ") | AA13: =IF(AND(AA$6>=$F13,AA$6<=$G13),"."," ") | AB13: =IF(AND(AB$6>=$F13,AB$6<=$G13),"."," ") -> . | AC13: =IF(AND(AC$6>=$F13,AC$6<=$G13),"."," ") -> . | AD13: =IF(AND(AD$6>=$F13,AD$6<=$G13),"."," ") -> . | AE13: =IF(AND(AE$6>=$F13,AE$6<=$G13),"."," ") -> . | AH13: =IF(AND(AH$6>=$F13,AH$6<=$G13),"."," ") | AI13: =IF(AND(AI$6>=$F13,AI$6<=$G13),"."," ") | AJ13: =IF(AND(AJ$6>=$F13,AJ$6<=$G13),"."," ") | AK13: =IF(AND(AK$6>=$F13,AK$6<=$G13),"."," ") | AL13: =IF(AND(AL$6>=$F13,AL$6<=$G13),"."," ") | AO13: =IF(AND(AO$6>=$F13,AO$6<=$G13),"."," ") | AP13: =IF(AND(AP$6>=$F13,AP$6<=$G13),"."," ") | AQ13: =IF(AND(AQ$6>=$F13,AQ$6<=$G13),"."," ") | AR13: =IF(AND(AR$6>=$F13,AR$6<=$G13),"."," ") | AS13: =IF(AND(AS$6>=$F13,AS$6<=$G13),"."," ") | AV13: =IF(AND(AV$6>=$F13,AV$6<=$G13),"."," ") | AW13: =IF(AND(AW$6>=$F13,AW$6<=$G13),"."," ") | AX13: =IF(AND(AX$6>=$F13,AX$6<=$G13),"."," ") | AY13: =IF(AND(AY$6>=$F13,AY$6<=$G13),"."," ") | AZ13: =IF(AND(AZ$6>=$F13,AZ$6<=$G13),"."," ") | BC13: =IF(AND(BC$6>=$F13,BC$6<=$G13),"."," ") | BD13: =IF(AND(BD$6>=$F13,BD$6<=$G13),"."," ") | BE13: =IF(AND(BE$6>=$F13,BE$6<=$G13),"."," ") | BF13: =IF(AND(BF$6>=$F13,BF$6<=$G13),"."," ") | BG13: =IF(AND(BG$6>=$F13,BG$6<=$G13),"."," ") | BJ13: =IF(AND(BJ$6>=$F13,BJ$6<=$G13),"."," ") | BK13: =IF(AND(BK$6>=$F13,BK$6<=$G13),"."," ") | BL13: =IF(AND(BL$6>=$F13,BL$6<=$G13),"."," ") | BM13: =IF(AND(BM$6>=$F13,BM$6<=$G13),"."," ") | BN13: =IF(AND(BN$6>=$F13,BN$6<=$G13),"."," ") | BQ13: =IF(AND(BQ$6>=$F13,BQ$6<=$G13),"."," ") | BR13: =IF(AND(BR$6>=$F13,BR$6<=$G13),"."," ") | BS13: =IF(AND(BS$6>=$F13,BS$6<=$G13),"."," ") | BT13: =IF(AND(BT$6>=$F13,BT$6<=$G13),"."," ") | BU13: =IF(AND(BU$6>=$F13,BU$6<=$G13),"."," ") | BX13: =IF(AND(BX$6>=$F13,BX$6<=$G13),"."," ") | BY13: =IF(AND(BY$6>=$F13,BY$6<=$G13),"."," ") | BZ13: =IF(AND(BZ$6>=$F13,BZ$6<=$G13),"."," ") | CA13: =IF(AND(CA$6>=$F13,CA$6<=$G13),"."," ") | CB13: =IF(AND(CB$6>=$F13,CB$6<=$G13),"."," ") | CE13: =IF(AND(CE$6>=$F13,CE$6<=$G13),"."," ") | CF13: =IF(AND(CF$6>=$F13,CF$6<=$G13),"."," ") | CG13: =IF(AND(CG$6>=$F13,CG$6<=$G13),"."," ") | CH13: =IF(AND(CH$6>=$F13,CH$6<=$G13),"."," ") | CI13: =IF(AND(CI$6>=$F13,CI$6<=$G13),"."," ") | CL13: =IF(AND(CL$6>=$F13,CL$6<=$G13),"."," ") | CM13: =IF(AND(CM$6>=$F13,CM$6<=$G13),"."," ") | CN13: =IF(AND(CN$6>=$F13,CN$6<=$G13),"."," ") | CO13: =IF(AND(CO$6>=$F13,CO$6<=$G13),"."," ") | CP13: =IF(AND(CP$6>=$F13,CP$6<=$G13),"."," ") | CS13: =IF(AND(CS$6>=$F13,CS$6<=$G13),"."," ") | CT13: =IF(AND(CT$6>=$F13,CT$6<=$G13),"."," ") | CU13: =IF(AND(CU$6>=$F13,CU$6<=$G13),"."," ") | CV13: =IF(AND(CV$6>=$F13,CV$6<=$G13),"."," ") | CW13: =IF(AND(CW$6>=$F13,CW$6<=$G13),"."," ") | CZ13: =IF(AND(CZ$6>=$F13,CZ$6<=$G13),"."," ") | DA13: =IF(AND(DA$6>=$F13,DA$6<=$G13),"."," ") | DB13: =IF(AND(DB$6>=$F13,DB$6<=$G13),"."," ") | DC13: =IF(AND(DC$6>=$F13,DC$6<=$G13),"."," ") | DD13: =IF(AND(DD$6>=$F13,DD$6<=$G13),"."," ") | DG13: =IF(AND(DG$6>=$F13,DG$6<=$G13),"."," ") | DH13: =IF(AND(DH$6>=$F13,DH$6<=$G13),"."," ") | DI13: =IF(AND(DI$6>=$F13,DI$6<=$G13),"."," ") | DJ13: =IF(AND(DJ$6>=$F13,DJ$6<=$G13),"."," ") | DK13: =IF(AND(DK$6>=$F13,DK$6<=$G13),"."," ") | DN13: =IF(AND(DN$6>=$F13,DN$6<=$G13),"."," ") | DO13: =IF(AND(DO$6>=$F13,DO$6<=$G13),"."," ") | DP13: =IF(AND(DP$6>=$F13,DP$6<=$G13),"."," ") | DQ13: =IF(AND(DQ$6>=$F13,DQ$6<=$G13),"."," ") | DR13: =IF(AND(DR$6>=$F13,DR$6<=$G13),"."," ") | DU13: =IF(AND(DU$6>=$F13,DU$6<=$G13),"."," ") | DV13: =IF(AND(DV$6>=$F13,DV$6<=$G13),"."," ") | DW13: =IF(AND(DW$6>=$F13,DW$6<=$G13),"."," ") | DX13: =IF(AND(DX$6>=$F13,DX$6<=$G13),"."," ") | DY13: =IF(AND(DY$6>=$F13,DY$6<=$G13),"."," ") | EB13: =IF(AND(EB$6>=$F13,EB$6<=$G13),"."," ") | EC13: =IF(AND(EC$6>=$F13,EC$6<=$G13),"."," ") | ED13: =IF(AND(ED$6>=$F13,ED$6<=$G13),"."," ") | EE13: =IF(AND(EE$6>=$F13,EE$6<=$G13),"."," ") | EF13: =IF(AND(EF$6>=$F13,EF$6<=$G13),"."," ") | EI13: =IF(AND(EI$6>=$F13,EI$6<=$G13),"."," ") | EJ13: =IF(AND(EJ$6>=$F13,EJ$6<=$G13),"."," ") | EK13: =IF(AND(EK$6>=$F13,EK$6<=$G13),"."," ") | EL13: =IF(AND(EL$6>=$F13,EL$6<=$G13),"."," ") | EM13: =IF(AND(EM$6>=$F13,EM$6<=$G13),"."," ") | EP13: =IF(AND(EP$6>=$F13,EP$6<=$G13),"."," ") | EQ13: =IF(AND(EQ$6>=$F13,EQ$6<=$G13),"."," ") | ER13: =IF(AND(ER$6>=$F13,ER$6<=$G13),"."," ") | ES13: =IF(AND(ES$6>=$F13,ES$6<=$G13),"."," ") | ET13: =IF(AND(ET$6>=$F13,ET$6<=$G13),"."," ") | EW13: =IF(AND(EW$6>=$F13,EW$6<=$G13),"."," ") | EX13: =IF(AND(EX$6>=$F13,EX$6<=$G13),"."," ") | EY13: =IF(AND(EY$6>=$F13,EY$6<=$G13),"."," ") | EZ13: =IF(AND(EZ$6>=$F13,EZ$6<=$G13),"."," ") | FA13: =IF(AND(FA$6>=$F13,FA$6<=$G13),"."," ") | FD13: =IF(AND(FD$6>=$F13,FD$6<=$G13),"."," ") | FE13: =IF(AND(FE$6>=$F13,FE$6<=$G13),"."," ") | FF13: =IF(AND(FF$6>=$F13,FF$6<=$G13),"."," ") | FG13: =IF(AND(FG$6>=$F13,FG$6<=$G13),"."," ") | FH13: =IF(AND(FH$6>=$F13,FH$6<=$G13),"."," ") | FK13: =IF(AND(FK$6>=$F13,FK$6<=$G13),"."," ") | FL13: =IF(AND(FL$6>=$F13,FL$6<=$G13),"."," ") | FM13: =IF(AND(FM$6>=$F13,FM$6<=$G13),"."," ") | FN13: =IF(AND(FN$6>=$F13,FN$6<=$G13),"."," ") | FO13: =IF(AND(FO$6>=$F13,FO$6<=$G13),"."," ") | FR13: =IF(AND(FR$6>=$F13,FR$6<=$G13),"."," ") | FS13: =IF(AND(FS$6>=$F13,FS$6<=$G13),"."," ") | FT13: =IF(AND(FT$6>=$F13,FT$6<=$G13),"."," ") | FU13: =IF(AND(FU$6>=$F13,FU$6<=$G13),"."," ") | FV13: =IF(AND(FV$6>=$F13,FV$6<=$G13),"."," ") | FY13: =IF(AND(FY$6>=$F13,FY$6<=$G13),"."," ") | FZ13: =IF(AND(FZ$6>=$F13,FZ$6<=$G13),"."," ") | GA13: =IF(AND(GA$6>=$F13,GA$6<=$G13),"."," ") | GB13: =IF(AND(GB$6>=$F13,GB$6<=$G13),"."," ") | GC13: =IF(AND(GC$6>=$F13,GC$6<=$G13),"."," ") | GF13: =IF(AND(GF$6>=$F13,GF$6<=$G13),"."," ") | GG13: =IF(AND(GG$6>=$F13,GG$6<=$G13),"."," ") | GH13: =IF(AND(GH$6>=$F13,GH$6<=$G13),"."," ") | GI13: =IF(AND(GI$6>=$F13,GI$6<=$G13),"."," ") | GJ13: =IF(AND(GJ$6>=$F13,GJ$6<=$G13),"."," ") | GM13: =IF(AND(GM$6>=$F13,GM$6<=$G13),"."," ") | GN13: =IF(AND(GN$6>=$F13,GN$6<=$G13),"."," ") | GO13: =IF(AND(GO$6>=$F13,GO$6<=$G13),"."," ") | GP13: =IF(AND(GP$6>=$F13,GP$6<=$G13),"."," ") | GQ13: =IF(AND(GQ$6>=$F13,GQ$6<=$G13),"."," ") | GT13: =IF(AND(GT$6>=$F13,GT$6<=$G13),"."," ") | GU13: =IF(AND(GU$6>=$F13,GU$6<=$G13),"."," ") | GV13: =IF(AND(GV$6>=$F13,GV$6<=$G13),"."," ") | GW13: =IF(AND(GW$6>=$F13,GW$6<=$G13),"."," ") | GX13: =IF(AND(GX$6>=$F13,GX$6<=$G13),"."," ") | HA13: =IF(AND(HA$6>=$F13,HA$6<=$G13),"."," ") | HB13: =IF(AND(HB$6>=$F13,HB$6<=$G13),"."," ") | HC13: =IF(AND(HC$6>=$F13,HC$6<=$G13),"."," ") | HD13: =IF(AND(HD$6>=$F13,HD$6<=$G13),"."," ") | HE13: =IF(AND(HE$6>=$F13,HE$6<=$G13),"."," ") | HH13: =IF(AND(HH$6>=$F13,HH$6<=$G13),"."," ") | HI13: =IF(AND(HI$6>=$F13,HI$6<=$G13),"."," ") | HJ13: =IF(AND(HJ$6>=$F13,HJ$6<=$G13),"."," ") | HK13: =IF(AND(HK$6>=$F13,HK$6<=$G13),"."," ") | HL13: =IF(AND(HL$6>=$F13,HL$6<=$G13),"."," ") | HO13: =IF(AND(HO$6>=$F13,HO$6<=$G13),"."," ") | HP13: =IF(AND(HP$6>=$F13,HP$6<=$G13),"."," ") | HQ13: =IF(AND(HQ$6>=$F13,HQ$6<=$G13),"."," ") | HR13: =IF(AND(HR$6>=$F13,HR$6<=$G13),"."," ") | HS13: =IF(AND(HS$6>=$F13,HS$6<=$G13),"."," ") | HV13: =IF(AND(HV$6>=$F13,HV$6<=$G13),"."," ") | HW13: =IF(AND(HW$6>=$F13,HW$6<=$G13),"."," ") | HX13: =IF(AND(HX$6>=$F13,HX$6<=$G13),"."," ") | HY13: =IF(AND(HY$6>=$F13,HY$6<=$G13),"."," ") | HZ13: =IF(AND(HZ$6>=$F13,HZ$6<=$G13),"."," ") | IC13: =IF(AND(IC$6>=$F13,IC$6<=$G13),"."," ") | ID13: =IF(AND(ID$6>=$F13,ID$6<=$G13),"."," ") | IE13: =IF(AND(IE$6>=$F13,IE$6<=$G13),"."," ") | IF13: =IF(AND(IF$6>=$F13,IF$6<=$G13),"."," ") | IG13: =IF(AND(IG$6>=$F13,IG$6<=$G13),"."," ") | IJ13: =IF(AND(IJ$6>=$F13,IJ$6<=$G13),"."," ") | IK13: =IF(AND(IK$6>=$F13,IK$6<=$G13),"."," ") | IL13: =IF(AND(IL$6>=$F13,IL$6<=$G13),"."," ") | IM13: =IF(AND(IM$6>=$F13,IM$6<=$G13),"."," ") | IN13: =IF(AND(IN$6>=$F13,IN$6<=$G13),"."," ") | IQ13: =IF(AND(IQ$6>=$F13,IQ$6<=$G13),"."," ") | IR13: =IF(AND(IR$6>=$F13,IR$6<=$G13),"."," ") | IS13: =IF(AND(IS$6>=$F13,IS$6<=$G13),"."," ") | IT13: =IF(AND(IT$6>=$F13,IT$6<=$G13),"."," ") | IU13: =IF(AND(IU$6>=$F13,IU$6<=$G13),"."," ") | IX13: =IF(AND(IX$6>=$F13,IX$6<=$G13),"."," ") | IY13: =IF(AND(IY$6>=$F13,IY$6<=$G13),"."," ") | IZ13: =IF(AND(IZ$6>=$F13,IZ$6<=$G13),"."," ") | JA13: =IF(AND(JA$6>=$F13,JA$6<=$G13),"."," ") | JB13: =IF(AND(JB$6>=$F13,JB$6<=$G13),"."," ") | JE13: =IF(AND(JE$6>=$F13,JE$6<=$G13),"."," ") | JF13: =IF(AND(JF$6>=$F13,JF$6<=$G13),"."," ") | JG13: =IF(AND(JG$6>=$F13,JG$6<=$G13),"."," ") | JH13: =IF(AND(JH$6>=$F13,JH$6<=$G13),"."," ") | JI13: =IF(AND(JI$6>=$F13,JI$6<=$G13),"."," ")
B14: =B13+1 -> 6 | C14: Requirements Discussions | D14: John | E14: 5 | F14: =VLOOKUP(E14,$B$6:$G$150,6,FALSE) + 1 -> 42515 | G14: =WORKDAY(F14,H14-1,Config!D12:D31) -> 42516 | H14: 2 | I14: 1 | J14: =IF(((NETWORKDAYS(F14,TODAY(),Data!C7:C26)*100)/H14)/100 > 0,((NETWORKDAYS(F14,TODAY(),Data!C7:C26)*100)/H14)/100,0) -> 829 | K14: =IF(J14>1, "100%",$J14) -> 100% | L14: =K14-I14 -> 0 | M14: =IF(AND(M$6>=$F14,M$6<=$G14),"."," ") | N14: =IF(AND(N$6>=$F14,N$6<=$G14),"."," ") | O14: =IF(AND(O$6>=$F14,O$6<=$G14),"."," ") | P14: =IF(AND(P$6>=$F14,P$6<=$G14),"."," ") | Q14: =IF(AND(Q$6>=$F14,Q$6<=$G14),"."," ") | T14: =IF(AND(T$6>=$F14,T$6<=$G14),"."," ") | U14: =IF(AND(U$6>=$F14,U$6<=$G14),"."," ") | V14: =IF(AND(V$6>=$F14,V$6<=$G14),"."," ") | W14: =IF(AND(W$6>=$F14,W$6<=$G14),"."," ") | X14: =IF(AND(X$6>=$F14,X$6<=$G14),"."," ") | AA14: =IF(AND(AA$6>=$F14,AA$6<=$G14),"."," ") | AB14: =IF(AND(AB$6>=$F14,AB$6<=$G14),"."," ") | AC14: =IF(AND(AC$6>=$F14,AC$6<=$G14),"."," ") | AD14: =IF(AND(AD$6>=$F14,AD$6<=$G14),"."," ") | AE14: =IF(AND(AE$6>=$F14,AE$6<=$G14),"."," ") | AH14: =IF(AND(AH$6>=$F14,AH$6<=$G14),"."," ") -> . | AI14: =IF(AND(AI$6>=$F14,AI$6<=$G14),"."," ") | AJ14: =IF(AND(AJ$6>=$F14,AJ$6<=$G14),"."," ") | AK14: =IF(AND(AK$6>=$F14,AK$6<=$G14),"."," ") | AL14: =IF(AND(AL$6>=$F14,AL$6<=$G14),"."," ") | AO14: =IF(AND(AO$6>=$F14,AO$6<=$G14),"."," ") | AP14: =IF(AND(AP$6>=$F14,AP$6<=$G14),"."," ") | AQ14: =IF(AND(AQ$6>=$F14,AQ$6<=$G14),"."," ") | AR14: =IF(AND(AR$6>=$F14,AR$6<=$G14),"."," ") | AS14: =IF(AND(AS$6>=$F14,AS$6<=$G14),"."," ") | AV14: =IF(AND(AV$6>=$F14,AV$6<=$G14),"."," ") | AW14: =IF(AND(AW$6>=$F14,AW$6<=$G14),"."," ") | AX14: =IF(AND(AX$6>=$F14,AX$6<=$G14),"."," ") | AY14: =IF(AND(AY$6>=$F14,AY$6<=$G14),"."," ") | AZ14: =IF(AND(AZ$6>=$F14,AZ$6<=$G14),"."," ") | BC14: =IF(AND(BC$6>=$F14,BC$6<=$G14),"."," ") | BD14: =IF(AND(BD$6>=$F14,BD$6<=$G14),"."," ") | BE14: =IF(AND(BE$6>=$F14,BE$6<=$G14),"."," ") | BF14: =IF(AND(BF$6>=$F14,BF$6<=$G14),"."," ") | BG14: =IF(AND(BG$6>=$F14,BG$6<=$G14),"."," ") | BJ14: =IF(AND(BJ$6>=$F14,BJ$6<=$G14),"."," ") | BK14: =IF(AND(BK$6>=$F14,BK$6<=$G14),"."," ") | BL14: =IF(AND(BL$6>=$F14,BL$6<=$G14),"."," ") | BM14: =IF(AND(BM$6>=$F14,BM$6<=$G14),"."," ") | BN14: =IF(AND(BN$6>=$F14,BN$6<=$G14),"."," ") | BQ14: =IF(AND(BQ$6>=$F14,BQ$6<=$G14),"."," ") | BR14: =IF(AND(BR$6>=$F14,BR$6<=$G14),"."," ") | BS14: =IF(AND(BS$6>=$F14,BS$6<=$G14),"."," ") | BT14: =IF(AND(BT$6>=$F14,BT$6<=$G14),"."," ") | BU14: =IF(AND(BU$6>=$F14,BU$6<=$G14),"."," ") | BX14: =IF(AND(BX$6>=$F14,BX$6<=$G14),"."," ") | BY14: =IF(AND(BY$6>=$F14,BY$6<=$G14),"."," ") | BZ14: =IF(AND(BZ$6>=$F14,BZ$6<=$G14),"."," ") | CA14: =IF(AND(CA$6>=$F14,CA$6<=$G14),"."," ") | CB14: =IF(AND(CB$6>=$F14,CB$6<=$G14),"."," ") | CE14: =IF(AND(CE$6>=$F14,CE$6<=$G14),"."," ") | CF14: =IF(AND(CF$6>=$F14,CF$6<=$G14),"."," ") | CG14: =IF(AND(CG$6>=$F14,CG$6<=$G14),"."," ") | CH14: =IF(AND(CH$6>=$F14,CH$6<=$G14),"."," ") | CI14: =IF(AND(CI$6>=$F14,CI$6<=$G14),"."," ") | CL14: =IF(AND(CL$6>=$F14,CL$6<=$G14),"."," ") | CM14: =IF(AND(CM$6>=$F14,CM$6<=$G14),"."," ") | CN14: =IF(AND(CN$6>=$F14,CN$6<=$G14),"."," ") | CO14: =IF(AND(CO$6>=$F14,CO$6<=$G14),"."," ") | CP14: =IF(AND(CP$6>=$F14,CP$6<=$G14),"."," ") | CS14: =IF(AND(CS$6>=$F14,CS$6<=$G14),"."," ") | CT14: =IF(AND(CT$6>=$F14,CT$6<=$G14),"."," ") | CU14: =IF(AND(CU$6>=$F14,CU$6<=$G14),"."," ") | CV14: =IF(AND(CV$6>=$F14,CV$6<=$G14),"."," ") | CW14: =IF(AND(CW$6>=$F14,CW$6<=$G14),"."," ") | CZ14: =IF(AND(CZ$6>=$F14,CZ$6<=$G14),"."," ") | DA14: =IF(AND(DA$6>=$F14,DA$6<=$G14),"."," ") | DB14: =IF(AND(DB$6>=$F14,DB$6<=$G14),"."," ") | DC14: =IF(AND(DC$6>=$F14,DC$6<=$G14),"."," ") | DD14: =IF(AND(DD$6>=$F14,DD$6<=$G14),"."," ") | DG14: =IF(AND(DG$6>=$F14,DG$6<=$G14),"."," ") | DH14: =IF(AND(DH$6>=$F14,DH$6<=$G14),"."," ") | DI14: =IF(AND(DI$6>=$F14,DI$6<=$G14),"."," ") | DJ14: =IF(AND(DJ$6>=$F14,DJ$6<=$G14),"."," ") | DK14: =IF(AND(DK$6>=$F14,DK$6<=$G14),"."," ") | DN14: =IF(AND(DN$6>=$F14,DN$6<=$G14),"."," ") | DO14: =IF(AND(DO$6>=$F14,DO$6<=$G14),"."," ") | DP14: =IF(AND(DP$6>=$F14,DP$6<=$G14),"."," ") | DQ14: =IF(AND(DQ$6>=$F14,DQ$6<=$G14),"."," ") | DR14: =IF(AND(DR$6>=$F14,DR$6<=$G14),"."," ") | DU14: =IF(AND(DU$6>=$F14,DU$6<=$G14),"."," ") | DV14: =IF(AND(DV$6>=$F14,DV$6<=$G14),"."," ") | DW14: =IF(AND(DW$6>=$F14,DW$6<=$G14),"."," ") | DX14: =IF(AND(DX$6>=$F14,DX$6<=$G14),"."," ") | DY14: =IF(AND(DY$6>=$F14,DY$6<=$G14),"."," ") | EB14: =IF(AND(EB$6>=$F14,EB$6<=$G14),"."," ") | EC14: =IF(AND(EC$6>=$F14,EC$6<=$G14),"."," ") | ED14: =IF(AND(ED$6>=$F14,ED$6<=$G14),"."," ") | EE14: =IF(AND(EE$6>=$F14,EE$6<=$G14),"."," ") | EF14: =IF(AND(EF$6>=$F14,EF$6<=$G14),"."," ") | EI14: =IF(AND(EI$6>=$F14,EI$6<=$G14),"."," ") | EJ14: =IF(AND(EJ$6>=$F14,EJ$6<=$G14),"."," ") | EK14: =IF(AND(EK$6>=$F14,EK$6<=$G14),"."," ") | EL14: =IF(AND(EL$6>=$F14,EL$6<=$G14),"."," ") | EM14: =IF(AND(EM$6>=$F14,EM$6<=$G14),"."," ") | EP14: =IF(AND(EP$6>=$F14,EP$6<=$G14),"."," ") | EQ14: =IF(AND(EQ$6>=$F14,EQ$6<=$G14),"."," ") | ER14: =IF(AND(ER$6>=$F14,ER$6<=$G14),"."," ") | ES14: =IF(AND(ES$6>=$F14,ES$6<=$G14),"."," ") | ET14: =IF(AND(ET$6>=$F14,ET$6<=$G14),"."," ") | EW14: =IF(AND(EW$6>=$F14,EW$6<=$G14),"."," ") | EX14: =IF(AND(EX$6>=$F14,EX$6<=$G14),"."," ") | EY14: =IF(AND(EY$6>=$F14,EY$6<=$G14),"."," ") | EZ14: =IF(AND(EZ$6>=$F14,EZ$6<=$G14),"."," ") | FA14: =IF(AND(FA$6>=$F14,FA$6<=$G14),"."," ") | FD14: =IF(AND(FD$6>=$F14,FD$6<=$G14),"."," ") | FE14: =IF(AND(FE$6>=$F14,FE$6<=$G14),"."," ") | FF14: =IF(AND(FF$6>=$F14,FF$6<=$G14),"."," ") | FG14: =IF(AND(FG$6>=$F14,FG$6<=$G14),"."," ") | FH14: =IF(AND(FH$6>=$F14,FH$6<=$G14),"."," ") | FK14: =IF(AND(FK$6>=$F14,FK$6<=$G14),"."," ") | FL14: =IF(AND(FL$6>=$F14,FL$6<=$G14),"."," ") | FM14: =IF(AND(FM$6>=$F14,FM$6<=$G14),"."," ") | FN14: =IF(AND(FN$6>=$F14,FN$6<=$G14),"."," ") | FO14: =IF(AND(FO$6>=$F14,FO$6<=$G14),"."," ") | FR14: =IF(AND(FR$6>=$F14,FR$6<=$G14),"."," ") | FS14: =IF(AND(FS$6>=$F14,FS$6<=$G14),"."," ") | FT14: =IF(AND(FT$6>=$F14,FT$6<=$G14),"."," ") | FU14: =IF(AND(FU$6>=$F14,FU$6<=$G14),"."," ") | FV14: =IF(AND(FV$6>=$F14,FV$6<=$G14),"."," ") | FY14: =IF(AND(FY$6>=$F14,FY$6<=$G14),"."," ") | FZ14: =IF(AND(FZ$6>=$F14,FZ$6<=$G14),"."," ") | GA14: =IF(AND(GA$6>=$F14,GA$6<=$G14),"."," ") | GB14: =IF(AND(GB$6>=$F14,GB$6<=$G14),"."," ") | GC14: =IF(AND(GC$6>=$F14,GC$6<=$G14),"."," ") | GF14: =IF(AND(GF$6>=$F14,GF$6<=$G14),"."," ") | GG14: =IF(AND(GG$6>=$F14,GG$6<=$G14),"."," ") | GH14: =IF(AND(GH$6>=$F14,GH$6<=$G14),"."," ") | GI14: =IF(AND(GI$6>=$F14,GI$6<=$G14),"."," ") | GJ14: =IF(AND(GJ$6>=$F14,GJ$6<=$G14),"."," ") | GM14: =IF(AND(GM$6>=$F14,GM$6<=$G14),"."," ") | GN14: =IF(AND(GN$6>=$F14,GN$6<=$G14),"."," ") | GO14: =IF(AND(GO$6>=$F14,GO$6<=$G14),"."," ") | GP14: =IF(AND(GP$6>=$F14,GP$6<=$G14),"."," ") | GQ14: =IF(AND(GQ$6>=$F14,GQ$6<=$G14),"."," ") | GT14: =IF(AND(GT$6>=$F14,GT$6<=$G14),"."," ") | GU14: =IF(AND(GU$6>=$F14,GU$6<=$G14),"."," ") | GV14: =IF(AND(GV$6>=$F14,GV$6<=$G14),"."," ") | GW14: =IF(AND(GW$6>=$F14,GW$6<=$G14),"."," ") | GX14: =IF(AND(GX$6>=$F14,GX$6<=$G14),"."," ") | HA14: =IF(AND(HA$6>=$F14,HA$6<=$G14),"."," ") | HB14: =IF(AND(HB$6>=$F14,HB$6<=$G14),"."," ") | HC14: =IF(AND(HC$6>=$F14,HC$6<=$G14),"."," ") | HD14: =IF(AND(HD$6>=$F14,HD$6<=$G14),"."," ") | HE14: =IF(AND(HE$6>=$F14,HE$6<=$G14),"."," ") | HH14: =IF(AND(HH$6>=$F14,HH$6<=$G14),"."," ") | HI14: =IF(AND(HI$6>=$F14,HI$6<=$G14),"."," ") | HJ14: =IF(AND(HJ$6>=$F14,HJ$6<=$G14),"."," ") | HK14: =IF(AND(HK$6>=$F14,HK$6<=$G14),"."," ") | HL14: =IF(AND(HL$6>=$F14,HL$6<=$G14),"."," ") | HO14: =IF(AND(HO$6>=$F14,HO$6<=$G14),"."," ") | HP14: =IF(AND(HP$6>=$F14,HP$6<=$G14),"."," ") | HQ14: =IF(AND(HQ$6>=$F14,HQ$6<=$G14),"."," ") | HR14: =IF(AND(HR$6>=$F14,HR$6<=$G14),"."," ") | HS14: =IF(AND(HS$6>=$F14,HS$6<=$G14),"."," ") | HV14: =IF(AND(HV$6>=$F14,HV$6<=$G14),"."," ") | HW14: =IF(AND(HW$6>=$F14,HW$6<=$G14),"."," ") | HX14: =IF(AND(HX$6>=$F14,HX$6<=$G14),"."," ") | HY14: =IF(AND(HY$6>=$F14,HY$6<=$G14),"."," ") | HZ14: =IF(AND(HZ$6>=$F14,HZ$6<=$G14),"."," ") | IC14: =IF(AND(IC$6>=$F14,IC$6<=$G14),"."," ") | ID14: =IF(AND(ID$6>=$F14,ID$6<=$G14),"."," ") | IE14: =IF(AND(IE$6>=$F14,IE$6<=$G14),"."," ") | IF14: =IF(AND(IF$6>=$F14,IF$6<=$G14),"."," ") | IG14: =IF(AND(IG$6>=$F14,IG$6<=$G14),"."," ") | IJ14: =IF(AND(IJ$6>=$F14,IJ$6<=$G14),"."," ") | IK14: =IF(AND(IK$6>=$F14,IK$6<=$G14),"."," ") | IL14: =IF(AND(IL$6>=$F14,IL$6<=$G14),"."," ") | IM14: =IF(AND(IM$6>=$F14,IM$6<=$G14),"."," ") | IN14: =IF(AND(IN$6>=$F14,IN$6<=$G14),"."," ") | IQ14: =IF(AND(IQ$6>=$F14,IQ$6<=$G14),"."," ") | IR14: =IF(AND(IR$6>=$F14,IR$6<=$G14),"."," ") | IS14: =IF(AND(IS$6>=$F14,IS$6<=$G14),"."," ") | IT14: =IF(AND(IT$6>=$F14,IT$6<=$G14),"."," ") | IU14: =IF(AND(IU$6>=$F14,IU$6<=$G14),"."," ") | IX14: =IF(AND(IX$6>=$F14,IX$6<=$G14),"."," ") | IY14: =IF(AND(IY$6>=$F14,IY$6<=$G14),"."," ") | IZ14: =IF(AND(IZ$6>=$F14,IZ$6<=$G14),"."," ") | JA14: =IF(AND(JA$6>=$F14,JA$6<=$G14),"."," ") | JB14: =IF(AND(JB$6>=$F14,JB$6<=$G14),"."," ") | JE14: =IF(AND(JE$6>=$F14,JE$6<=$G14),"."," ") | JF14: =IF(AND(JF$6>=$F14,JF$6<=$G14),"."," ") | JG14: =IF(AND(JG$6>=$F14,JG$6<=$G14),"."," ") | JH14: =IF(AND(JH$6>=$F14,JH$6<=$G14),"."," ") | JI14: =IF(AND(JI$6>=$F14,JI$6<=$G14),"."," ")
