Workbook
Name Current_Rating: '[1]Risks Register'!$M$14:$M$38
Name Impact: [1]Ratings!$D$9:$H$9
Name Issues_Rating: [1]Ratings!$D$19:$H$20
Name Likelihood: [1]Ratings!$C$4:$C$8

Sheet Info
B6: Info
B7: This excel file is composed by four tabs: • Risk Register • Risk Range & Risk Matrix, • Lists (hidden tab needs to be unhidden to be edited) and, • Info
B8: Risk Register is composed by three different type of fields. Conditioned fields and Automatic fields and Free fields. Conditioned fields means the user can only select from a dropdown menu list and the content and/or format will be populated after selection. Automatic fields means the content and/or format will self-populate according to other conditioned fileds inputed in the same row. Free fields means the user can type without restrictions. Conditioned fileds are in Type (column G), Urgency (column H), Category (column I), Characteristic (column J), Likelihood (columns K and S), Impact (columns M and U), Treatment (Q & Y). Automatic fields are Risk rating (columns P and X ), Likelihood formula (columns L and T ), Impact formula (columns N and V) and Risk rating formula (columns O and W) The rest are free fields. It is recomeneded to leave the automaticn fields Formula columns (L,T,N,V,O and W) hidden. The Risk register is currently programmed for 100 risks initially as an example, but this can be easily be extended if further rows are needed.
B9: Risk Range and Risk Matrix Risk range and Risk Matrix are interlinked with each other and are linked to the Risk Register. Changing editable fields (yellow filled cells) can be done to adjust the risk ranges and impact and likelihood values to be aligned with the project risk assessment policy.
B10: Lists The list fields contains stored info used for dropdown menu conditioned fileds in the Risk Register tab

Sheet Risk Register
B6: Risk Register
B7: Identification | G7: Categorization | K7: Risk Assessment | Q7: Treatment | S7: Re-assessment | Y7: Treatment | AA7: Monitoring
B8: Rn-id | C8: Reported by | D8: Date | E8: Description | F8: Owner | G8: Type | H8: Urgency | I8: Category | J8: Characteristic | K8: Likelihood | L8: Likelihood formula | M8: Impact | N8: Impact formula | O8: Risk Rating formula | P8: Risk Rating | Q8: Treatment | R8: Description | S8: Likelihood | T8: Likelihood formula | U8: Impact | V8: Impact formula | W8: Risk Rating formula | X8: Risk Rating | Y8: Treatment | Z8: Description | AA8: Comments | AB8: Last updated
B9: R1 | G9: Internal | H9: High | I9: Technical | J9: Positive | K9: Unlikely | L9: =IF(K9='Risk Range & Risk Matrix'!$G$12,'Risk Range & Risk Matrix'!$H$12,IF(K9='Risk Range & Risk Matrix'!$G$11,'Risk Range & Risk Matrix'!$H$11,IF(K9='Risk Range & Risk Matrix'!$G$10,'Risk Range & Risk Matrix'!$H$10,IF(K9='Risk Range & Risk Matrix'!$G$9,'Risk Range & Risk Matrix'!$H$9,IF(K9='Risk Range & Risk Matrix'!$G$8,'Risk Range & Risk Matrix'!$H$8,""))))) -> 1 | M9: Insignificant | N9: =IF(M9='Risk Range & Risk Matrix'!$I$6,'Risk Range & Risk Matrix'!$I$7,IF(M9='Risk Range & Risk Matrix'!$J$6,'Risk Range & Risk Matrix'!$J$7,IF(M9='Risk Range & Risk Matrix'!$K$6,'Risk Range & Risk Matrix'!$K$7,IF(M9='Risk Range & Risk Matrix'!$L$6,'Risk Range & Risk Matrix'!$L$7,IF(M9='Risk Range & Risk Matrix'!$M$6,'Risk Range & Risk Matrix'!$M$7,""))))) -> 1 | O9: =IF(OR(L9="",N9=""),"empty",L9*N9) -> 1 | P9: =O9 -> 1 | S9: Unlikely | T9: =IF(S9='Risk Range & Risk Matrix'!$G$12,'Risk Range & Risk Matrix'!$H$12,IF(S9='Risk Range & Risk Matrix'!$G$11,'Risk Range & Risk Matrix'!$H$11,IF(S9='Risk Range & Risk Matrix'!$G$10,'Risk Range & Risk Matrix'!$H$10,IF(S9='Risk Range & Risk Matrix'!$G$9,'Risk Range & Risk Matrix'!$H$9,IF(S9='Risk Range & Risk Matrix'!$G$8,'Risk Range & Risk Matrix'!$H$8,""))))) -> 1 | U9: Insignificant | V9: =IF(U9='Risk Range & Risk Matrix'!$I$6,'Risk Range & Risk Matrix'!$I$7,IF(U9='Risk Range & Risk Matrix'!$J$6,'Risk Range & Risk Matrix'!$J$7,IF(U9='Risk Range & Risk Matrix'!$K$6,'Risk Range & Risk Matrix'!$K$7,IF(U9='Risk Range & Risk Matrix'!$L$6,'Risk Range & Risk Matrix'!$L$7,IF(U9='Risk Range & Risk Matrix'!$M$6,'Risk Range & Risk Matrix'!$M$7,""))))) -> 1 | W9: =IF(OR(T9="",V9=""),"empty",T9*V9) -> 1 | X9: =W9 -> 1
B10: R2 | G10: External | H10: Medium | I10: Cost | J10: Negative | K10: Likely | L10: =IF(K10='Risk Range & Risk Matrix'!$G$12,'Risk Range & Risk Matrix'!$H$12,IF(K10='Risk Range & Risk Matrix'!$G$11,'Risk Range & Risk Matrix'!$H$11,IF(K10='Risk Range & Risk Matrix'!$G$10,'Risk Range & Risk Matrix'!$H$10,IF(K10='Risk Range & Risk Matrix'!$G$9,'Risk Range & Risk Matrix'!$H$9,IF(K10='Risk Range & Risk Matrix'!$G$8,'Risk Range & Risk Matrix'!$H$8,""))))) -> 2 | M10: Minor | N10: =IF(M10='Risk Range & Risk Matrix'!$I$6,'Risk Range & Risk Matrix'!$I$7,IF(M10='Risk Range & Risk Matrix'!$J$6,'Risk Range & Risk Matrix'!$J$7,IF(M10='Risk Range & Risk Matrix'!$K$6,'Risk Range & Risk Matrix'!$K$7,IF(M10='Risk Range & Risk Matrix'!$L$6,'Risk Range & Risk Matrix'!$L$7,IF(M10='Risk Range & Risk Matrix'!$M$6,'Risk Range & Risk Matrix'!$M$7,""))))) -> 2 | O10: =IF(OR(L10="",N10=""),"empty",L10*N10) -> 4 | P10: =O10 -> 4 | Q10: Accept | S10: Likely | T10: =IF(S10='Risk Range & Risk Matrix'!$G$12,'Risk Range & Risk Matrix'!$H$12,IF(S10='Risk Range & Risk Matrix'!$G$11,'Risk Range & Risk Matrix'!$H$11,IF(S10='Risk Range & Risk Matrix'!$G$10,'Risk Range & Risk Matrix'!$H$10,IF(S10='Risk Range & Risk Matrix'!$G$9,'Risk Range & Risk Matrix'!$H$9,IF(S10='Risk Range & Risk Matrix'!$G$8,'Risk Range & Risk Matrix'!$H$8,""))))) -> 2 | U10: Minor | V10: =IF(U10='Risk Range & Risk Matrix'!$I$6,'Risk Range & Risk Matrix'!$I$7,IF(U10='Risk Range & Risk Matrix'!$J$6,'Risk Range & Risk Matrix'!$J$7,IF(U10='Risk Range & Risk Matrix'!$K$6,'Risk Range & Risk Matrix'!$K$7,IF(U10='Risk Range & Risk Matrix'!$L$6,'Risk Range & Risk Matrix'!$L$7,IF(U10='Risk Range & Risk Matrix'!$M$6,'Risk Range & Risk Matrix'!$M$7,""))))) -> 2 | W10: =IF(OR(T10="",V10=""),"empty",T10*V10) -> 4 | X10: =W10 -> 4 | Y10: Accept
B11: R3 | H11: Low | I11: Schedule | K11: Possible | L11: =IF(K11='Risk Range & Risk Matrix'!$G$12,'Risk Range & Risk Matrix'!$H$12,IF(K11='Risk Range & Risk Matrix'!$G$11,'Risk Range & Risk Matrix'!$H$11,IF(K11='Risk Range & Risk Matrix'!$G$10,'Risk Range & Risk Matrix'!$H$10,IF(K11='Risk Range & Risk Matrix'!$G$9,'Risk Range & Risk Matrix'!$H$9,IF(K11='Risk Range & Risk Matrix'!$G$8,'Risk Range & Risk Matrix'!$H$8,""))))) -> 2 | M11: Moderate | N11: =IF(M11='Risk Range & Risk Matrix'!$I$6,'Risk Range & Risk Matrix'!$I$7,IF(M11='Risk Range & Risk Matrix'!$J$6,'Risk Range & Risk Matrix'!$J$7,IF(M11='Risk Range & Risk Matrix'!$K$6,'Risk Range & Risk Matrix'!$K$7,IF(M11='Risk Range & Risk Matrix'!$L$6,'Risk Range & Risk Matrix'!$L$7,IF(M11='Risk Range & Risk Matrix'!$M$6,'Risk Range & Risk Matrix'!$M$7,""))))) -> 3 | O11: =IF(OR(L11="",N11=""),"empty",L11*N11) -> 6 | P11: =O11 -> 6 | Q11: Transfer | S11: Possible | T11: =IF(S11='Risk Range & Risk Matrix'!$G$12,'Risk Range & Risk Matrix'!$H$12,IF(S11='Risk Range & Risk Matrix'!$G$11,'Risk Range & Risk Matrix'!$H$11,IF(S11='Risk Range & Risk Matrix'!$G$10,'Risk Range & Risk Matrix'!$H$10,IF(S11='Risk Range & Risk Matrix'!$G$9,'Risk Range & Risk Matrix'!$H$9,IF(S11='Risk Range & Risk Matrix'!$G$8,'Risk Range & Risk Matrix'!$H$8,""))))) -> 2 | U11: Moderate | V11: =IF(U11='Risk Range & Risk Matrix'!$I$6,'Risk Range & Risk Matrix'!$I$7,IF(U11='Risk Range & Risk Matrix'!$J$6,'Risk Range & Risk Matrix'!$J$7,IF(U11='Risk Range & Risk Matrix'!$K$6,'Risk Range & Risk Matrix'!$K$7,IF(U11='Risk Range & Risk Matrix'!$L$6,'Risk Range & Risk Matrix'!$L$7,IF(U11='Risk Range & Risk Matrix'!$M$6,'Risk Range & Risk Matrix'!$M$7,""))))) -> 3 | W11: =IF(OR(T11="",V11=""),"empty",T11*V11) -> 6 | X11: =W11 -> 6 | Y11: Transfer
B12: R4 | I12: Contractual | K12: Very likely | L12: =IF(K12='Risk Range & Risk Matrix'!$G$12,'Risk Range & Risk Matrix'!$H$12,IF(K12='Risk Range & Risk Matrix'!$G$11,'Risk Range & Risk Matrix'!$H$11,IF(K12='Risk Range & Risk Matrix'!$G$10,'Risk Range & Risk Matrix'!$H$10,IF(K12='Risk Range & Risk Matrix'!$G$9,'Risk Range & Risk Matrix'!$H$9,IF(K12='Risk Range & Risk Matrix'!$G$8,'Risk Range & Risk Matrix'!$H$8,""))))) -> 4 | M12: Major | N12: =IF(M12='Risk Range & Risk Matrix'!$I$6,'Risk Range & Risk Matrix'!$I$7,IF(M12='Risk Range & Risk Matrix'!$J$6,'Risk Range & Risk Matrix'!$J$7,IF(M12='Risk Range & Risk Matrix'!$K$6,'Risk Range & Risk Matrix'!$K$7,IF(M12='Risk Range & Risk Matrix'!$L$6,'Risk Range & Risk Matrix'!$L$7,IF(M12='Risk Range & Risk Matrix'!$M$6,'Risk Range & Risk Matrix'!$M$7,""))))) -> 4 | O12: =IF(OR(L12="",N12=""),"empty",L12*N12) -> 16 | P12: =O12 -> 16 | Q12: Mitigate | S12: Very likely | T12: =IF(S12='Risk Range & Risk Matrix'!$G$12,'Risk Range & Risk Matrix'!$H$12,IF(S12='Risk Range & Risk Matrix'!$G$11,'Risk Range & Risk Matrix'!$H$11,IF(S12='Risk Range & Risk Matrix'!$G$10,'Risk Range & Risk Matrix'!$H$10,IF(S12='Risk Range & Risk Matrix'!$G$9,'Risk Range & Risk Matrix'!$H$9,IF(S12='Risk Range & Risk Matrix'!$G$8,'Risk Range & Risk Matrix'!$H$8,""))))) -> 4 | U12: Major | V12: =IF(U12='Risk Range & Risk Matrix'!$I$6,'Risk Range & Risk Matrix'!$I$7,IF(U12='Risk Range & Risk Matrix'!$J$6,'Risk Range & Risk Matrix'!$J$7,IF(U12='Risk Range & Risk Matrix'!$K$6,'Risk Range & Risk Matrix'!$K$7,IF(U12='Risk Range & Risk Matrix'!$L$6,'Risk Range & Risk Matrix'!$L$7,IF(U12='Risk Range & Risk Matrix'!$M$6,'Risk Range & Risk Matrix'!$M$7,""))))) -> 4 | W12: =IF(OR(T12="",V12=""),"empty",T12*V12) -> 16 | X12: =W12 -> 16 | Y12: Mitigate
B13: R5 | I13: Weather | K13: Almost certain | L13: =IF(K13='Risk Range & Risk Matrix'!$G$12,'Risk Range & Risk Matrix'!$H$12,IF(K13='Risk Range & Risk Matrix'!$G$11,'Risk Range & Risk Matrix'!$H$11,IF(K13='Risk Range & Risk Matrix'!$G$10,'Risk Range & Risk Matrix'!$H$10,IF(K13='Risk Range & Risk Matrix'!$G$9,'Risk Range & Risk Matrix'!$H$9,IF(K13='Risk Range & Risk Matrix'!$G$8,'Risk Range & Risk Matrix'!$H$8,""))))) -> 5 | M13: Catastrophic | N13: =IF(M13='Risk Range & Risk Matrix'!$I$6,'Risk Range & Risk Matrix'!$I$7,IF(M13='Risk Range & Risk Matrix'!$J$6,'Risk Range & Risk Matrix'!$J$7,IF(M13='Risk Range & Risk Matrix'!$K$6,'Risk Range & Risk Matrix'!$K$7,IF(M13='Risk Range & Risk Matrix'!$L$6,'Risk Range & Risk Matrix'!$L$7,IF(M13='Risk Range & Risk Matrix'!$M$6,'Risk Range & Risk Matrix'!$M$7,""))))) -> 5 | O13: =IF(OR(L13="",N13=""),"empty",L13*N13) -> 25 | P13: =O13 -> 25 | Q13: Avoid | S13: Almost certain | T13: =IF(S13='Risk Range & Risk Matrix'!$G$12,'Risk Range & Risk Matrix'!$H$12,IF(S13='Risk Range & Risk Matrix'!$G$11,'Risk Range & Risk Matrix'!$H$11,IF(S13='Risk Range & Risk Matrix'!$G$10,'Risk Range & Risk Matrix'!$H$10,IF(S13='Risk Range & Risk Matrix'!$G$9,'Risk Range & Risk Matrix'!$H$9,IF(S13='Risk Range & Risk Matrix'!$G$8,'Risk Range & Risk Matrix'!$H$8,""))))) -> 5 | U13: Catastrophic | V13: =IF(U13='Risk Range & Risk Matrix'!$I$6,'Risk Range & Risk Matrix'!$I$7,IF(U13='Risk Range & Risk Matrix'!$J$6,'Risk Range & Risk Matrix'!$J$7,IF(U13='Risk Range & Risk Matrix'!$K$6,'Risk Range & Risk Matrix'!$K$7,IF(U13='Risk Range & Risk Matrix'!$L$6,'Risk Range & Risk Matrix'!$L$7,IF(U13='Risk Range & Risk Matrix'!$M$6,'Risk Range & Risk Matrix'!$M$7,""))))) -> 5 | W13: =IF(OR(T13="",V13=""),"empty",T13*V13) -> 25 | X13: =W13 -> 25 | Y13: Avoid
B14: R6 | I14: Quality | L14: =IF(K14='Risk Range & Risk Matrix'!$G$12,'Risk Range & Risk Matrix'!$H$12,IF(K14='Risk Range & Risk Matrix'!$G$11,'Risk Range & Risk Matrix'!$H$11,IF(K14='Risk Range & Risk Matrix'!$G$10,'Risk Range & Risk Matrix'!$H$10,IF(K14='Risk Range & Risk Matrix'!$G$9,'Risk Range & Risk Matrix'!$H$9,IF(K14='Risk Range & Risk Matrix'!$G$8,'Risk Range & Risk Matrix'!$H$8,""))))) | N14: =IF(M14='Risk Range & Risk Matrix'!$I$6,'Risk Range & Risk Matrix'!$I$7,IF(M14='Risk Range & Risk Matrix'!$J$6,'Risk Range & Risk Matrix'!$J$7,IF(M14='Risk Range & Risk Matrix'!$K$6,'Risk Range & Risk Matrix'!$K$7,IF(M14='Risk Range & Risk Matrix'!$L$6,'Risk Range & Risk Matrix'!$L$7,IF(M14='Risk Range & Risk Matrix'!$M$6,'Risk Range & Risk Matrix'!$M$7,""))))) | O14: =IF(OR(L14="",N14=""),"empty",L14*N14) -> empty | P14: =O14 -> empty | Q14: Exploit potential | T14: =IF(S14='Risk Range & Risk Matrix'!$G$12,'Risk Range & Risk Matrix'!$H$12,IF(S14='Risk Range & Risk Matrix'!$G$11,'Risk Range & Risk Matrix'!$H$11,IF(S14='Risk Range & Risk Matrix'!$G$10,'Risk Range & Risk Matrix'!$H$10,IF(S14='Risk Range & Risk Matrix'!$G$9,'Risk Range & Risk Matrix'!$H$9,IF(S14='Risk Range & Risk Matrix'!$G$8,'Risk Range & Risk Matrix'!$H$8,""))))) | V14: =IF(U14='Risk Range & Risk Matrix'!$I$6,'Risk Range & Risk Matrix'!$I$7,IF(U14='Risk Range & Risk Matrix'!$J$6,'Risk Range & Risk Matrix'!$J$7,IF(U14='Risk Range & Risk Matrix'!$K$6,'Risk Range & Risk Matrix'!$K$7,IF(U14='Risk Range & Risk Matrix'!$L$6,'Risk Range & Risk Matrix'!$L$7,IF(U14='Risk Range & Risk Matrix'!$M$6,'Risk Range & Risk Matrix'!$M$7,""))))) | W14: =IF(OR(T14="",V14=""),"empty",T14*V14) -> empty | X14: =W14 -> empty | Y14: Exploit potential
B15: R7 | I15: Financial | L15: =IF(K15='Risk Range & Risk Matrix'!$G$12,'Risk Range & Risk Matrix'!$H$12,IF(K15='Risk Range & Risk Matrix'!$G$11,'Risk Range & Risk Matrix'!$H$11,IF(K15='Risk Range & Risk Matrix'!$G$10,'Risk Range & Risk Matrix'!$H$10,IF(K15='Risk Range & Risk Matrix'!$G$9,'Risk Range & Risk Matrix'!$H$9,IF(K15='Risk Range & Risk Matrix'!$G$8,'Risk Range & Risk Matrix'!$H$8,""))))) | N15: =IF(M15='Risk Range & Risk Matrix'!$I$6,'Risk Range & Risk Matrix'!$I$7,IF(M15='Risk Range & Risk Matrix'!$J$6,'Risk Range & Risk Matrix'!$J$7,IF(M15='Risk Range & Risk Matrix'!$K$6,'Risk Range & Risk Matrix'!$K$7,IF(M15='Risk Range & Risk Matrix'!$L$6,'Risk Range & Risk Matrix'!$L$7,IF(M15='Risk Range & Risk Matrix'!$M$6,'Risk Range & Risk Matrix'!$M$7,""))))) | O15: =IF(OR(L15="",N15=""),"empty",L15*N15) -> empty | P15: =O15 -> empty | Q15: Share | T15: =IF(S15='Risk Range & Risk Matrix'!$G$12,'Risk Range & Risk Matrix'!$H$12,IF(S15='Risk Range & Risk Matrix'!$G$11,'Risk Range & Risk Matrix'!$H$11,IF(S15='Risk Range & Risk Matrix'!$G$10,'Risk Range & Risk Matrix'!$H$10,IF(S15='Risk Range & Risk Matrix'!$G$9,'Risk Range & Risk Matrix'!$H$9,IF(S15='Risk Range & Risk Matrix'!$G$8,'Risk Range & Risk Matrix'!$H$8,""))))) | V15: =IF(U15='Risk Range & Risk Matrix'!$I$6,'Risk Range & Risk Matrix'!$I$7,IF(U15='Risk Range & Risk Matrix'!$J$6,'Risk Range & Risk Matrix'!$J$7,IF(U15='Risk Range & Risk Matrix'!$K$6,'Risk Range & Risk Matrix'!$K$7,IF(U15='Risk Range & Risk Matrix'!$L$6,'Risk Range & Risk Matrix'!$L$7,IF(U15='Risk Range & Risk Matrix'!$M$6,'Risk Range & Risk Matrix'!$M$7,""))))) | W15: =IF(OR(T15="",V15=""),"empty",T15*V15) -> empty | X15: =W15 -> empty | Y15: Share
B16: R8 | I16: Political | L16: =IF(K16='Risk Range & Risk Matrix'!$G$12,'Risk Range & Risk Matrix'!$H$12,IF(K16='Risk Range & Risk Matrix'!$G$11,'Risk Range & Risk Matrix'!$H$11,IF(K16='Risk Range & Risk Matrix'!$G$10,'Risk Range & Risk Matrix'!$H$10,IF(K16='Risk Range & Risk Matrix'!$G$9,'Risk Range & Risk Matrix'!$H$9,IF(K16='Risk Range & Risk Matrix'!$G$8,'Risk Range & Risk Matrix'!$H$8,""))))) | N16: =IF(M16='Risk Range & Risk Matrix'!$I$6,'Risk Range & Risk Matrix'!$I$7,IF(M16='Risk Range & Risk Matrix'!$J$6,'Risk Range & Risk Matrix'!$J$7,IF(M16='Risk Range & Risk Matrix'!$K$6,'Risk Range & Risk Matrix'!$K$7,IF(M16='Risk Range & Risk Matrix'!$L$6,'Risk Range & Risk Matrix'!$L$7,IF(M16='Risk Range & Risk Matrix'!$M$6,'Risk Range & Risk Matrix'!$M$7,""))))) | O16: =IF(OR(L16="",N16=""),"empty",L16*N16) -> empty | P16: =O16 -> empty | T16: =IF(S16='Risk Range & Risk Matrix'!$G$12,'Risk Range & Risk Matrix'!$H$12,IF(S16='Risk Range & Risk Matrix'!$G$11,'Risk Range & Risk Matrix'!$H$11,IF(S16='Risk Range & Risk Matrix'!$G$10,'Risk Range & Risk Matrix'!$H$10,IF(S16='Risk Range & Risk Matrix'!$G$9,'Risk Range & Risk Matrix'!$H$9,IF(S16='Risk Range & Risk Matrix'!$G$8,'Risk Range & Risk Matrix'!$H$8,""))))) | V16: =IF(U16='Risk Range & Risk Matrix'!$I$6,'Risk Range & Risk Matrix'!$I$7,IF(U16='Risk Range & Risk Matrix'!$J$6,'Risk Range & Risk Matrix'!$J$7,IF(U16='Risk Range & Risk Matrix'!$K$6,'Risk Range & Risk Matrix'!$K$7,IF(U16='Risk Range & Risk Matrix'!$L$6,'Risk Range & Risk Matrix'!$L$7,IF(U16='Risk Range & Risk Matrix'!$M$6,'Risk Range & Risk Matrix'!$M$7,""))))) | W16: =IF(OR(T16="",V16=""),"empty",T16*V16) -> empty | X16: =W16 -> empty
B17: R9 | I17: Environmental | L17: =IF(K17='Risk Range & Risk Matrix'!$G$12,'Risk Range & Risk Matrix'!$H$12,IF(K17='Risk Range & Risk Matrix'!$G$11,'Risk Range & Risk Matrix'!$H$11,IF(K17='Risk Range & Risk Matrix'!$G$10,'Risk Range & Risk Matrix'!$H$10,IF(K17='Risk Range & Risk Matrix'!$G$9,'Risk Range & Risk Matrix'!$H$9,IF(K17='Risk Range & Risk Matrix'!$G$8,'Risk Range & Risk Matrix'!$H$8,""))))) | N17: =IF(M17='Risk Range & Risk Matrix'!$I$6,'Risk Range & Risk Matrix'!$I$7,IF(M17='Risk Range & Risk Matrix'!$J$6,'Risk Range & Risk Matrix'!$J$7,IF(M17='Risk Range & Risk Matrix'!$K$6,'Risk Range & Risk Matrix'!$K$7,IF(M17='Risk Range & Risk Matrix'!$L$6,'Risk Range & Risk Matrix'!$L$7,IF(M17='Risk Range & Risk Matrix'!$M$6,'Risk Range & Risk Matrix'!$M$7,""))))) | O17: =IF(OR(L17="",N17=""),"empty",L17*N17) -> empty | P17: =O17 -> empty | T17: =IF(S17='Risk Range & Risk Matrix'!$G$12,'Risk Range & Risk Matrix'!$H$12,IF(S17='Risk Range & Risk Matrix'!$G$11,'Risk Range & Risk Matrix'!$H$11,IF(S17='Risk Range & Risk Matrix'!$G$10,'Risk Range & Risk Matrix'!$H$10,IF(S17='Risk Range & Risk Matrix'!$G$9,'Risk Range & Risk Matrix'!$H$9,IF(S17='Risk Range & Risk Matrix'!$G$8,'Risk Range & Risk Matrix'!$H$8,""))))) | V17: =IF(U17='Risk Range & Risk Matrix'!$I$6,'Risk Range & Risk Matrix'!$I$7,IF(U17='Risk Range & Risk Matrix'!$J$6,'Risk Range & Risk Matrix'!$J$7,IF(U17='Risk Range & Risk Matrix'!$K$6,'Risk Range & Risk Matrix'!$K$7,IF(U17='Risk Range & Risk Matrix'!$L$6,'Risk Range & Risk Matrix'!$L$7,IF(U17='Risk Range & Risk Matrix'!$M$6,'Risk Range & Risk Matrix'!$M$7,""))))) | W17: =IF(OR(T17="",V17=""),"empty",T17*V17) -> empty | X17: =W17 -> empty
B18: R10 | I18: Safety | L18: =IF(K18='Risk Range & Risk Matrix'!$G$12,'Risk Range & Risk Matrix'!$H$12,IF(K18='Risk Range & Risk Matrix'!$G$11,'Risk Range & Risk Matrix'!$H$11,IF(K18='Risk Range & Risk Matrix'!$G$10,'Risk Range & Risk Matrix'!$H$10,IF(K18='Risk Range & Risk Matrix'!$G$9,'Risk Range & Risk Matrix'!$H$9,IF(K18='Risk Range & Risk Matrix'!$G$8,'Risk Range & Risk Matrix'!$H$8,""))))) | N18: =IF(M18='Risk Range & Risk Matrix'!$I$6,'Risk Range & Risk Matrix'!$I$7,IF(M18='Risk Range & Risk Matrix'!$J$6,'Risk Range & Risk Matrix'!$J$7,IF(M18='Risk Range & Risk Matrix'!$K$6,'Risk Range & Risk Matrix'!$K$7,IF(M18='Risk Range & Risk Matrix'!$L$6,'Risk Range & Risk Matrix'!$L$7,IF(M18='Risk Range & Risk Matrix'!$M$6,'Risk Range & Risk Matrix'!$M$7,""))))) | O18: =IF(OR(L18="",N18=""),"empty",L18*N18) -> empty | P18: =O18 -> empty | T18: =IF(S18='Risk Range & Risk Matrix'!$G$12,'Risk Range & Risk Matrix'!$H$12,IF(S18='Risk Range & Risk Matrix'!$G$11,'Risk Range & Risk Matrix'!$H$11,IF(S18='Risk Range & Risk Matrix'!$G$10,'Risk Range & Risk Matrix'!$H$10,IF(S18='Risk Range & Risk Matrix'!$G$9,'Risk Range & Risk Matrix'!$H$9,IF(S18='Risk Range & Risk Matrix'!$G$8,'Risk Range & Risk Matrix'!$H$8,""))))) | V18: =IF(U18='Risk Range & Risk Matrix'!$I$6,'Risk Range & Risk Matrix'!$I$7,IF(U18='Risk Range & Risk Matrix'!$J$6,'Risk Range & Risk Matrix'!$J$7,IF(U18='Risk Range & Risk Matrix'!$K$6,'Risk Range & Risk Matrix'!$K$7,IF(U18='Risk Range & Risk Matrix'!$L$6,'Risk Range & Risk Matrix'!$L$7,IF(U18='Risk Range & Risk Matrix'!$M$6,'Risk Range & Risk Matrix'!$M$7,""))))) | W18: =IF(OR(T18="",V18=""),"empty",T18*V18) -> empty | X18: =W18 -> empty
B19: R11 | I19: Resources | L19: =IF(K19='Risk Range & Risk Matrix'!$G$12,'Risk Range & Risk Matrix'!$H$12,IF(K19='Risk Range & Risk Matrix'!$G$11,'Risk Range & Risk Matrix'!$H$11,IF(K19='Risk Range & Risk Matrix'!$G$10,'Risk Range & Risk Matrix'!$H$10,IF(K19='Risk Range & Risk Matrix'!$G$9,'Risk Range & Risk Matrix'!$H$9,IF(K19='Risk Range & Risk Matrix'!$G$8,'Risk Range & Risk Matrix'!$H$8,""))))) | N19: =IF(M19='Risk Range & Risk Matrix'!$I$6,'Risk Range & Risk Matrix'!$I$7,IF(M19='Risk Range & Risk Matrix'!$J$6,'Risk Range & Risk Matrix'!$J$7,IF(M19='Risk Range & Risk Matrix'!$K$6,'Risk Range & Risk Matrix'!$K$7,IF(M19='Risk Range & Risk Matrix'!$L$6,'Risk Range & Risk Matrix'!$L$7,IF(M19='Risk Range & Risk Matrix'!$M$6,'Risk Range & Risk Matrix'!$M$7,""))))) | O19: =IF(OR(L19="",N19=""),"empty",L19*N19) -> empty | P19: =O19 -> empty | T19: =IF(S19='Risk Range & Risk Matrix'!$G$12,'Risk Range & Risk Matrix'!$H$12,IF(S19='Risk Range & Risk Matrix'!$G$11,'Risk Range & Risk Matrix'!$H$11,IF(S19='Risk Range & Risk Matrix'!$G$10,'Risk Range & Risk Matrix'!$H$10,IF(S19='Risk Range & Risk Matrix'!$G$9,'Risk Range & Risk Matrix'!$H$9,IF(S19='Risk Range & Risk Matrix'!$G$8,'Risk Range & Risk Matrix'!$H$8,""))))) | V19: =IF(U19='Risk Range & Risk Matrix'!$I$6,'Risk Range & Risk Matrix'!$I$7,IF(U19='Risk Range & Risk Matrix'!$J$6,'Risk Range & Risk Matrix'!$J$7,IF(U19='Risk Range & Risk Matrix'!$K$6,'Risk Range & Risk Matrix'!$K$7,IF(U19='Risk Range & Risk Matrix'!$L$6,'Risk Range & Risk Matrix'!$L$7,IF(U19='Risk Range & Risk Matrix'!$M$6,'Risk Range & Risk Matrix'!$M$7,""))))) | W19: =IF(OR(T19="",V19=""),"empty",T19*V19) -> empty | X19: =W19 -> empty
B20: R12 | I20: Regulatory | L20: =IF(K20='Risk Range & Risk Matrix'!$G$12,'Risk Range & Risk Matrix'!$H$12,IF(K20='Risk Range & Risk Matrix'!$G$11,'Risk Range & Risk Matrix'!$H$11,IF(K20='Risk Range & Risk Matrix'!$G$10,'Risk Range & Risk Matrix'!$H$10,IF(K20='Risk Range & Risk Matrix'!$G$9,'Risk Range & Risk Matrix'!$H$9,IF(K20='Risk Range & Risk Matrix'!$G$8,'Risk Range & Risk Matrix'!$H$8,""))))) | N20: =IF(M20='Risk Range & Risk Matrix'!$I$6,'Risk Range & Risk Matrix'!$I$7,IF(M20='Risk Range & Risk Matrix'!$J$6,'Risk Range & Risk Matrix'!$J$7,IF(M20='Risk Range & Risk Matrix'!$K$6,'Risk Range & Risk Matrix'!$K$7,IF(M20='Risk Range & Risk Matrix'!$L$6,'Risk Range & Risk Matrix'!$L$7,IF(M20='Risk Range & Risk Matrix'!$M$6,'Risk Range & Risk Matrix'!$M$7,""))))) | O20: =IF(OR(L20="",N20=""),"empty",L20*N20) -> empty | P20: =O20 -> empty | T20: =IF(S20='Risk Range & Risk Matrix'!$G$12,'Risk Range & Risk Matrix'!$H$12,IF(S20='Risk Range & Risk Matrix'!$G$11,'Risk Range & Risk Matrix'!$H$11,IF(S20='Risk Range & Risk Matrix'!$G$10,'Risk Range & Risk Matrix'!$H$10,IF(S20='Risk Range & Risk Matrix'!$G$9,'Risk Range & Risk Matrix'!$H$9,IF(S20='Risk Range & Risk Matrix'!$G$8,'Risk Range & Risk Matrix'!$H$8,""))))) | V20: =IF(U20='Risk Range & Risk Matrix'!$I$6,'Risk Range & Risk Matrix'!$I$7,IF(U20='Risk Range & Risk Matrix'!$J$6,'Risk Range & Risk Matrix'!$J$7,IF(U20='Risk Range & Risk Matrix'!$K$6,'Risk Range & Risk Matrix'!$K$7,IF(U20='Risk Range & Risk Matrix'!$L$6,'Risk Range & Risk Matrix'!$L$7,IF(U20='Risk Range & Risk Matrix'!$M$6,'Risk Range & Risk Matrix'!$M$7,""))))) | W20: =IF(OR(T20="",V20=""),"empty",T20*V20) -> empty | X20: =W20 -> empty
B21: R13 | I21: Dependencies | L21: =IF(K21='Risk Range & Risk Matrix'!$G$12,'Risk Range & Risk Matrix'!$H$12,IF(K21='Risk Range & Risk Matrix'!$G$11,'Risk Range & Risk Matrix'!$H$11,IF(K21='Risk Range & Risk Matrix'!$G$10,'Risk Range & Risk Matrix'!$H$10,IF(K21='Risk Range & Risk Matrix'!$G$9,'Risk Range & Risk Matrix'!$H$9,IF(K21='Risk Range & Risk Matrix'!$G$8,'Risk Range & Risk Matrix'!$H$8,""))))) | N21: =IF(M21='Risk Range & Risk Matrix'!$I$6,'Risk Range & Risk Matrix'!$I$7,IF(M21='Risk Range & Risk Matrix'!$J$6,'Risk Range & Risk Matrix'!$J$7,IF(M21='Risk Range & Risk Matrix'!$K$6,'Risk Range & Risk Matrix'!$K$7,IF(M21='Risk Range & Risk Matrix'!$L$6,'Risk Range & Risk Matrix'!$L$7,IF(M21='Risk Range & Risk Matrix'!$M$6,'Risk Range & Risk Matrix'!$M$7,""))))) | O21: =IF(OR(L21="",N21=""),"empty",L21*N21) -> empty | P21: =O21 -> empty | T21: =IF(S21='Risk Range & Risk Matrix'!$G$12,'Risk Range & Risk Matrix'!$H$12,IF(S21='Risk Range & Risk Matrix'!$G$11,'Risk Range & Risk Matrix'!$H$11,IF(S21='Risk Range & Risk Matrix'!$G$10,'Risk Range & Risk Matrix'!$H$10,IF(S21='Risk Range & Risk Matrix'!$G$9,'Risk Range & Risk Matrix'!$H$9,IF(S21='Risk Range & Risk Matrix'!$G$8,'Risk Range & Risk Matrix'!$H$8,""))))) | V21: =IF(U21='Risk Range & Risk Matrix'!$I$6,'Risk Range & Risk Matrix'!$I$7,IF(U21='Risk Range & Risk Matrix'!$J$6,'Risk Range & Risk Matrix'!$J$7,IF(U21='Risk Range & Risk Matrix'!$K$6,'Risk Range & Risk Matrix'!$K$7,IF(U21='Risk Range & Risk Matrix'!$L$6,'Risk Range & Risk Matrix'!$L$7,IF(U21='Risk Range & Risk Matrix'!$M$6,'Risk Range & Risk Matrix'!$M$7,""))))) | W21: =IF(OR(T21="",V21=""),"empty",T21*V21) -> empty | X21: =W21 -> empty
B22: R14 | I22: Market | L22: =IF(K22='Risk Range & Risk Matrix'!$G$12,'Risk Range & Risk Matrix'!$H$12,IF(K22='Risk Range & Risk Matrix'!$G$11,'Risk Range & Risk Matrix'!$H$11,IF(K22='Risk Range & Risk Matrix'!$G$10,'Risk Range & Risk Matrix'!$H$10,IF(K22='Risk Range & Risk Matrix'!$G$9,'Risk Range & Risk Matrix'!$H$9,IF(K22='Risk Range & Risk Matrix'!$G$8,'Risk Range & Risk Matrix'!$H$8,""))))) | N22: =IF(M22='Risk Range & Risk Matrix'!$I$6,'Risk Range & Risk Matrix'!$I$7,IF(M22='Risk Range & Risk Matrix'!$J$6,'Risk Range & Risk Matrix'!$J$7,IF(M22='Risk Range & Risk Matrix'!$K$6,'Risk Range & Risk Matrix'!$K$7,IF(M22='Risk Range & Risk Matrix'!$L$6,'Risk Range & Risk Matrix'!$L$7,IF(M22='Risk Range & Risk Matrix'!$M$6,'Risk Range & Risk Matrix'!$M$7,""))))) | O22: =IF(OR(L22="",N22=""),"empty",L22*N22) -> empty | P22: =O22 -> empty | T22: =IF(S22='Risk Range & Risk Matrix'!$G$12,'Risk Range & Risk Matrix'!$H$12,IF(S22='Risk Range & Risk Matrix'!$G$11,'Risk Range & Risk Matrix'!$H$11,IF(S22='Risk Range & Risk Matrix'!$G$10,'Risk Range & Risk Matrix'!$H$10,IF(S22='Risk Range & Risk Matrix'!$G$9,'Risk Range & Risk Matrix'!$H$9,IF(S22='Risk Range & Risk Matrix'!$G$8,'Risk Range & Risk Matrix'!$H$8,""))))) | V22: =IF(U22='Risk Range & Risk Matrix'!$I$6,'Risk Range & Risk Matrix'!$I$7,IF(U22='Risk Range & Risk Matrix'!$J$6,'Risk Range & Risk Matrix'!$J$7,IF(U22='Risk Range & Risk Matrix'!$K$6,'Risk Range & Risk Matrix'!$K$7,IF(U22='Risk Range & Risk Matrix'!$L$6,'Risk Range & Risk Matrix'!$L$7,IF(U22='Risk Range & Risk Matrix'!$M$6,'Risk Range & Risk Matrix'!$M$7,""))))) | W22: =IF(OR(T22="",V22=""),"empty",T22*V22) -> empty | X22: =W22 -> empty
B23: R15 | I23: Legal | L23: =IF(K23='Risk Range & Risk Matrix'!$G$12,'Risk Range & Risk Matrix'!$H$12,IF(K23='Risk Range & Risk Matrix'!$G$11,'Risk Range & Risk Matrix'!$H$11,IF(K23='Risk Range & Risk Matrix'!$G$10,'Risk Range & Risk Matrix'!$H$10,IF(K23='Risk Range & Risk Matrix'!$G$9,'Risk Range & Risk Matrix'!$H$9,IF(K23='Risk Range & Risk Matrix'!$G$8,'Risk Range & Risk Matrix'!$H$8,""))))) | N23: =IF(M23='Risk Range & Risk Matrix'!$I$6,'Risk Range & Risk Matrix'!$I$7,IF(M23='Risk Range & Risk Matrix'!$J$6,'Risk Range & Risk Matrix'!$J$7,IF(M23='Risk Range & Risk Matrix'!$K$6,'Risk Range & Risk Matrix'!$K$7,IF(M23='Risk Range & Risk Matrix'!$L$6,'Risk Range & Risk Matrix'!$L$7,IF(M23='Risk Range & Risk Matrix'!$M$6,'Risk Range & Risk Matrix'!$M$7,""))))) | O23: =IF(OR(L23="",N23=""),"empty",L23*N23) -> empty | P23: =O23 -> empty | T23: =IF(S23='Risk Range & Risk Matrix'!$G$12,'Risk Range & Risk Matrix'!$H$12,IF(S23='Risk Range & Risk Matrix'!$G$11,'Risk Range & Risk Matrix'!$H$11,IF(S23='Risk Range & Risk Matrix'!$G$10,'Risk Range & Risk Matrix'!$H$10,IF(S23='Risk Range & Risk Matrix'!$G$9,'Risk Range & Risk Matrix'!$H$9,IF(S23='Risk Range & Risk Matrix'!$G$8,'Risk Range & Risk Matrix'!$H$8,""))))) | V23: =IF(U23='Risk Range & Risk Matrix'!$I$6,'Risk Range & Risk Matrix'!$I$7,IF(U23='Risk Range & Risk Matrix'!$J$6,'Risk Range & Risk Matrix'!$J$7,IF(U23='Risk Range & Risk Matrix'!$K$6,'Risk Range & Risk Matrix'!$K$7,IF(U23='Risk Range & Risk Matrix'!$L$6,'Risk Range & Risk Matrix'!$L$7,IF(U23='Risk Range & Risk Matrix'!$M$6,'Risk Range & Risk Matrix'!$M$7,""))))) | W23: =IF(OR(T23="",V23=""),"empty",T23*V23) -> empty | X23: =W23 -> empty
B24: R16 | I24: Ethical | L24: =IF(K24='Risk Range & Risk Matrix'!$G$12,'Risk Range & Risk Matrix'!$H$12,IF(K24='Risk Range & Risk Matrix'!$G$11,'Risk Range & Risk Matrix'!$H$11,IF(K24='Risk Range & Risk Matrix'!$G$10,'Risk Range & Risk Matrix'!$H$10,IF(K24='Risk Range & Risk Matrix'!$G$9,'Risk Range & Risk Matrix'!$H$9,IF(K24='Risk Range & Risk Matrix'!$G$8,'Risk Range & Risk Matrix'!$H$8,""))))) | N24: =IF(M24='Risk Range & Risk Matrix'!$I$6,'Risk Range & Risk Matrix'!$I$7,IF(M24='Risk Range & Risk Matrix'!$J$6,'Risk Range & Risk Matrix'!$J$7,IF(M24='Risk Range & Risk Matrix'!$K$6,'Risk Range & Risk Matrix'!$K$7,IF(M24='Risk Range & Risk Matrix'!$L$6,'Risk Range & Risk Matrix'!$L$7,IF(M24='Risk Range & Risk Matrix'!$M$6,'Risk Range & Risk Matrix'!$M$7,""))))) | O24: =IF(OR(L24="",N24=""),"empty",L24*N24) -> empty | P24: =O24 -> empty | T24: =IF(S24='Risk Range & Risk Matrix'!$G$12,'Risk Range & Risk Matrix'!$H$12,IF(S24='Risk Range & Risk Matrix'!$G$11,'Risk Range & Risk Matrix'!$H$11,IF(S24='Risk Range & Risk Matrix'!$G$10,'Risk Range & Risk Matrix'!$H$10,IF(S24='Risk Range & Risk Matrix'!$G$9,'Risk Range & Risk Matrix'!$H$9,IF(S24='Risk Range & Risk Matrix'!$G$8,'Risk Range & Risk Matrix'!$H$8,""))))) | V24: =IF(U24='Risk Range & Risk Matrix'!$I$6,'Risk Range & Risk Matrix'!$I$7,IF(U24='Risk Range & Risk Matrix'!$J$6,'Risk Range & Risk Matrix'!$J$7,IF(U24='Risk Range & Risk Matrix'!$K$6,'Risk Range & Risk Matrix'!$K$7,IF(U24='Risk Range & Risk Matrix'!$L$6,'Risk Range & Risk Matrix'!$L$7,IF(U24='Risk Range & Risk Matrix'!$M$6,'Risk Range & Risk Matrix'!$M$7,""))))) | W24: =IF(OR(T24="",V24=""),"empty",T24*V24) -> empty | X24: =W24 -> empty
B25: R17 | I25: Reputation | L25: =IF(K25='Risk Range & Risk Matrix'!$G$12,'Risk Range & Risk Matrix'!$H$12,IF(K25='Risk Range & Risk Matrix'!$G$11,'Risk Range & Risk Matrix'!$H$11,IF(K25='Risk Range & Risk Matrix'!$G$10,'Risk Range & Risk Matrix'!$H$10,IF(K25='Risk Range & Risk Matrix'!$G$9,'Risk Range & Risk Matrix'!$H$9,IF(K25='Risk Range & Risk Matrix'!$G$8,'Risk Range & Risk Matrix'!$H$8,""))))) | N25: =IF(M25='Risk Range & Risk Matrix'!$I$6,'Risk Range & Risk Matrix'!$I$7,IF(M25='Risk Range & Risk Matrix'!$J$6,'Risk Range & Risk Matrix'!$J$7,IF(M25='Risk Range & Risk Matrix'!$K$6,'Risk Range & Risk Matrix'!$K$7,IF(M25='Risk Range & Risk Matrix'!$L$6,'Risk Range & Risk Matrix'!$L$7,IF(M25='Risk Range & Risk Matrix'!$M$6,'Risk Range & Risk Matrix'!$M$7,""))))) | O25: =IF(OR(L25="",N25=""),"empty",L25*N25) -> empty | P25: =O25 -> empty | T25: =IF(S25='Risk Range & Risk Matrix'!$G$12,'Risk Range & Risk Matrix'!$H$12,IF(S25='Risk Range & Risk Matrix'!$G$11,'Risk Range & Risk Matrix'!$H$11,IF(S25='Risk Range & Risk Matrix'!$G$10,'Risk Range & Risk Matrix'!$H$10,IF(S25='Risk Range & Risk Matrix'!$G$9,'Risk Range & Risk Matrix'!$H$9,IF(S25='Risk Range & Risk Matrix'!$G$8,'Risk Range & Risk Matrix'!$H$8,""))))) | V25: =IF(U25='Risk Range & Risk Matrix'!$I$6,'Risk Range & Risk Matrix'!$I$7,IF(U25='Risk Range & Risk Matrix'!$J$6,'Risk Range & Risk Matrix'!$J$7,IF(U25='Risk Range & Risk Matrix'!$K$6,'Risk Range & Risk Matrix'!$K$7,IF(U25='Risk Range & Risk Matrix'!$L$6,'Risk Range & Risk Matrix'!$L$7,IF(U25='Risk Range & Risk Matrix'!$M$6,'Risk Range & Risk Matrix'!$M$7,""))))) | W25: =IF(OR(T25="",V25=""),"empty",T25*V25) -> empty | X25: =W25 -> empty
B26: R18 | I26: Community | L26: =IF(K26='Risk Range & Risk Matrix'!$G$12,'Risk Range & Risk Matrix'!$H$12,IF(K26='Risk Range & Risk Matrix'!$G$11,'Risk Range & Risk Matrix'!$H$11,IF(K26='Risk Range & Risk Matrix'!$G$10,'Risk Range & Risk Matrix'!$H$10,IF(K26='Risk Range & Risk Matrix'!$G$9,'Risk Range & Risk Matrix'!$H$9,IF(K26='Risk Range & Risk Matrix'!$G$8,'Risk Range & Risk Matrix'!$H$8,""))))) | N26: =IF(M26='Risk Range & Risk Matrix'!$I$6,'Risk Range & Risk Matrix'!$I$7,IF(M26='Risk Range & Risk Matrix'!$J$6,'Risk Range & Risk Matrix'!$J$7,IF(M26='Risk Range & Risk Matrix'!$K$6,'Risk Range & Risk Matrix'!$K$7,IF(M26='Risk Range & Risk Matrix'!$L$6,'Risk Range & Risk Matrix'!$L$7,IF(M26='Risk Range & Risk Matrix'!$M$6,'Risk Range & Risk Matrix'!$M$7,""))))) | O26: =IF(OR(L26="",N26=""),"empty",L26*N26) -> empty | P26: =O26 -> empty | T26: =IF(S26='Risk Range & Risk Matrix'!$G$12,'Risk Range & Risk Matrix'!$H$12,IF(S26='Risk Range & Risk Matrix'!$G$11,'Risk Range & Risk Matrix'!$H$11,IF(S26='Risk Range & Risk Matrix'!$G$10,'Risk Range & Risk Matrix'!$H$10,IF(S26='Risk Range & Risk Matrix'!$G$9,'Risk Range & Risk Matrix'!$H$9,IF(S26='Risk Range & Risk Matrix'!$G$8,'Risk Range & Risk Matrix'!$H$8,""))))) | V26: =IF(U26='Risk Range & Risk Matrix'!$I$6,'Risk Range & Risk Matrix'!$I$7,IF(U26='Risk Range & Risk Matrix'!$J$6,'Risk Range & Risk Matrix'!$J$7,IF(U26='Risk Range & Risk Matrix'!$K$6,'Risk Range & Risk Matrix'!$K$7,IF(U26='Risk Range & Risk Matrix'!$L$6,'Risk Range & Risk Matrix'!$L$7,IF(U26='Risk Range & Risk Matrix'!$M$6,'Risk Range & Risk Matrix'!$M$7,""))))) | W26: =IF(OR(T26="",V26=""),"empty",T26*V26) -> empty | X26: =W26 -> empty
B27: R19 | I27: Heritage | L27: =IF(K27='Risk Range & Risk Matrix'!$G$12,'Risk Range & Risk Matrix'!$H$12,IF(K27='Risk Range & Risk Matrix'!$G$11,'Risk Range & Risk Matrix'!$H$11,IF(K27='Risk Range & Risk Matrix'!$G$10,'Risk Range & Risk Matrix'!$H$10,IF(K27='Risk Range & Risk Matrix'!$G$9,'Risk Range & Risk Matrix'!$H$9,IF(K27='Risk Range & Risk Matrix'!$G$8,'Risk Range & Risk Matrix'!$H$8,""))))) | N27: =IF(M27='Risk Range & Risk Matrix'!$I$6,'Risk Range & Risk Matrix'!$I$7,IF(M27='Risk Range & Risk Matrix'!$J$6,'Risk Range & Risk Matrix'!$J$7,IF(M27='Risk Range & Risk Matrix'!$K$6,'Risk Range & Risk Matrix'!$K$7,IF(M27='Risk Range & Risk Matrix'!$L$6,'Risk Range & Risk Matrix'!$L$7,IF(M27='Risk Range & Risk Matrix'!$M$6,'Risk Range & Risk Matrix'!$M$7,""))))) | O27: =IF(OR(L27="",N27=""),"empty",L27*N27) -> empty | P27: =O27 -> empty | T27: =IF(S27='Risk Range & Risk Matrix'!$G$12,'Risk Range & Risk Matrix'!$H$12,IF(S27='Risk Range & Risk Matrix'!$G$11,'Risk Range & Risk Matrix'!$H$11,IF(S27='Risk Range & Risk Matrix'!$G$10,'Risk Range & Risk Matrix'!$H$10,IF(S27='Risk Range & Risk Matrix'!$G$9,'Risk Range & Risk Matrix'!$H$9,IF(S27='Risk Range & Risk Matrix'!$G$8,'Risk Range & Risk Matrix'!$H$8,""))))) | V27: =IF(U27='Risk Range & Risk Matrix'!$I$6,'Risk Range & Risk Matrix'!$I$7,IF(U27='Risk Range & Risk Matrix'!$J$6,'Risk Range & Risk Matrix'!$J$7,IF(U27='Risk Range & Risk Matrix'!$K$6,'Risk Range & Risk Matrix'!$K$7,IF(U27='Risk Range & Risk Matrix'!$L$6,'Risk Range & Risk Matrix'!$L$7,IF(U27='Risk Range & Risk Matrix'!$M$6,'Risk Range & Risk Matrix'!$M$7,""))))) | W27: =IF(OR(T27="",V27=""),"empty",T27*V27) -> empty | X27: =W27 -> empty
B28: R20 | I28: Other | L28: =IF(K28='Risk Range & Risk Matrix'!$G$12,'Risk Range & Risk Matrix'!$H$12,IF(K28='Risk Range & Risk Matrix'!$G$11,'Risk Range & Risk Matrix'!$H$11,IF(K28='Risk Range & Risk Matrix'!$G$10,'Risk Range & Risk Matrix'!$H$10,IF(K28='Risk Range & Risk Matrix'!$G$9,'Risk Range & Risk Matrix'!$H$9,IF(K28='Risk Range & Risk Matrix'!$G$8,'Risk Range & Risk Matrix'!$H$8,""))))) | N28: =IF(M28='Risk Range & Risk Matrix'!$I$6,'Risk Range & Risk Matrix'!$I$7,IF(M28='Risk Range & Risk Matrix'!$J$6,'Risk Range & Risk Matrix'!$J$7,IF(M28='Risk Range & Risk Matrix'!$K$6,'Risk Range & Risk Matrix'!$K$7,IF(M28='Risk Range & Risk Matrix'!$L$6,'Risk Range & Risk Matrix'!$L$7,IF(M28='Risk Range & Risk Matrix'!$M$6,'Risk Range & Risk Matrix'!$M$7,""))))) | O28: =IF(OR(L28="",N28=""),"empty",L28*N28) -> empty | P28: =O28 -> empty | T28: =IF(S28='Risk Range & Risk Matrix'!$G$12,'Risk Range & Risk Matrix'!$H$12,IF(S28='Risk Range & Risk Matrix'!$G$11,'Risk Range & Risk Matrix'!$H$11,IF(S28='Risk Range & Risk Matrix'!$G$10,'Risk Range & Risk Matrix'!$H$10,IF(S28='Risk Range & Risk Matrix'!$G$9,'Risk Range & Risk Matrix'!$H$9,IF(S28='Risk Range & Risk Matrix'!$G$8,'Risk Range & Risk Matrix'!$H$8,""))))) | V28: =IF(U28='Risk Range & Risk Matrix'!$I$6,'Risk Range & Risk Matrix'!$I$7,IF(U28='Risk Range & Risk Matrix'!$J$6,'Risk Range & Risk Matrix'!$J$7,IF(U28='Risk Range & Risk Matrix'!$K$6,'Risk Range & Risk Matrix'!$K$7,IF(U28='Risk Range & Risk Matrix'!$L$6,'Risk Range & Risk Matrix'!$L$7,IF(U28='Risk Range & Risk Matrix'!$M$6,'Risk Range & Risk Matrix'!$M$7,""))))) | W28: =IF(OR(T28="",V28=""),"empty",T28*V28) -> empty | X28: =W28 -> empty
B29: R21 | L29: =IF(K29='Risk Range & Risk Matrix'!$G$12,'Risk Range & Risk Matrix'!$H$12,IF(K29='Risk Range & Risk Matrix'!$G$11,'Risk Range & Risk Matrix'!$H$11,IF(K29='Risk Range & Risk Matrix'!$G$10,'Risk Range & Risk Matrix'!$H$10,IF(K29='Risk Range & Risk Matrix'!$G$9,'Risk Range & Risk Matrix'!$H$9,IF(K29='Risk Range & Risk Matrix'!$G$8,'Risk Range & Risk Matrix'!$H$8,""))))) | N29: =IF(M29='Risk Range & Risk Matrix'!$I$6,'Risk Range & Risk Matrix'!$I$7,IF(M29='Risk Range & Risk Matrix'!$J$6,'Risk Range & Risk Matrix'!$J$7,IF(M29='Risk Range & Risk Matrix'!$K$6,'Risk Range & Risk Matrix'!$K$7,IF(M29='Risk Range & Risk Matrix'!$L$6,'Risk Range & Risk Matrix'!$L$7,IF(M29='Risk Range & Risk Matrix'!$M$6,'Risk Range & Risk Matrix'!$M$7,""))))) | O29: =IF(OR(L29="",N29=""),"empty",L29*N29) -> empty | P29: =O29 -> empty | T29: =IF(S29='Risk Range & Risk Matrix'!$G$12,'Risk Range & Risk Matrix'!$H$12,IF(S29='Risk Range & Risk Matrix'!$G$11,'Risk Range & Risk Matrix'!$H$11,IF(S29='Risk Range & Risk Matrix'!$G$10,'Risk Range & Risk Matrix'!$H$10,IF(S29='Risk Range & Risk Matrix'!$G$9,'Risk Range & Risk Matrix'!$H$9,IF(S29='Risk Range & Risk Matrix'!$G$8,'Risk Range & Risk Matrix'!$H$8,""))))) | V29: =IF(U29='Risk Range & Risk Matrix'!$I$6,'Risk Range & Risk Matrix'!$I$7,IF(U29='Risk Range & Risk Matrix'!$J$6,'Risk Range & Risk Matrix'!$J$7,IF(U29='Risk Range & Risk Matrix'!$K$6,'Risk Range & Risk Matrix'!$K$7,IF(U29='Risk Range & Risk Matrix'!$L$6,'Risk Range & Risk Matrix'!$L$7,IF(U29='Risk Range & Risk Matrix'!$M$6,'Risk Range & Risk Matrix'!$M$7,""))))) | W29: =IF(OR(T29="",V29=""),"empty",T29*V29) -> empty | X29: =W29 -> empty
B30: R22 | L30: =IF(K30='Risk Range & Risk Matrix'!$G$12,'Risk Range & Risk Matrix'!$H$12,IF(K30='Risk Range & Risk Matrix'!$G$11,'Risk Range & Risk Matrix'!$H$11,IF(K30='Risk Range & Risk Matrix'!$G$10,'Risk Range & Risk Matrix'!$H$10,IF(K30='Risk Range & Risk Matrix'!$G$9,'Risk Range & Risk Matrix'!$H$9,IF(K30='Risk Range & Risk Matrix'!$G$8,'Risk Range & Risk Matrix'!$H$8,""))))) | N30: =IF(M30='Risk Range & Risk Matrix'!$I$6,'Risk Range & Risk Matrix'!$I$7,IF(M30='Risk Range & Risk Matrix'!$J$6,'Risk Range & Risk Matrix'!$J$7,IF(M30='Risk Range & Risk Matrix'!$K$6,'Risk Range & Risk Matrix'!$K$7,IF(M30='Risk Range & Risk Matrix'!$L$6,'Risk Range & Risk Matrix'!$L$7,IF(M30='Risk Range & Risk Matrix'!$M$6,'Risk Range & Risk Matrix'!$M$7,""))))) | O30: =IF(OR(L30="",N30=""),"empty",L30*N30) -> empty | P30: =O30 -> empty | T30: =IF(S30='Risk Range & Risk Matrix'!$G$12,'Risk Range & Risk Matrix'!$H$12,IF(S30='Risk Range & Risk Matrix'!$G$11,'Risk Range & Risk Matrix'!$H$11,IF(S30='Risk Range & Risk Matrix'!$G$10,'Risk Range & Risk Matrix'!$H$10,IF(S30='Risk Range & Risk Matrix'!$G$9,'Risk Range & Risk Matrix'!$H$9,IF(S30='Risk Range & Risk Matrix'!$G$8,'Risk Range & Risk Matrix'!$H$8,""))))) | V30: =IF(U30='Risk Range & Risk Matrix'!$I$6,'Risk Range & Risk Matrix'!$I$7,IF(U30='Risk Range & Risk Matrix'!$J$6,'Risk Range & Risk Matrix'!$J$7,IF(U30='Risk Range & Risk Matrix'!$K$6,'Risk Range & Risk Matrix'!$K$7,IF(U30='Risk Range & Risk Matrix'!$L$6,'Risk Range & Risk Matrix'!$L$7,IF(U30='Risk Range & Risk Matrix'!$M$6,'Risk Range & Risk Matrix'!$M$7,""))))) | W30: =IF(OR(T30="",V30=""),"empty",T30*V30) -> empty | X30: =W30 -> empty
B31: R23 | L31: =IF(K31='Risk Range & Risk Matrix'!$G$12,'Risk Range & Risk Matrix'!$H$12,IF(K31='Risk Range & Risk Matrix'!$G$11,'Risk Range & Risk Matrix'!$H$11,IF(K31='Risk Range & Risk Matrix'!$G$10,'Risk Range & Risk Matrix'!$H$10,IF(K31='Risk Range & Risk Matrix'!$G$9,'Risk Range & Risk Matrix'!$H$9,IF(K31='Risk Range & Risk Matrix'!$G$8,'Risk Range & Risk Matrix'!$H$8,""))))) | N31: =IF(M31='Risk Range & Risk Matrix'!$I$6,'Risk Range & Risk Matrix'!$I$7,IF(M31='Risk Range & Risk Matrix'!$J$6,'Risk Range & Risk Matrix'!$J$7,IF(M31='Risk Range & Risk Matrix'!$K$6,'Risk Range & Risk Matrix'!$K$7,IF(M31='Risk Range & Risk Matrix'!$L$6,'Risk Range & Risk Matrix'!$L$7,IF(M31='Risk Range & Risk Matrix'!$M$6,'Risk Range & Risk Matrix'!$M$7,""))))) | O31: =IF(OR(L31="",N31=""),"empty",L31*N31) -> empty | P31: =O31 -> empty | T31: =IF(S31='Risk Range & Risk Matrix'!$G$12,'Risk Range & Risk Matrix'!$H$12,IF(S31='Risk Range & Risk Matrix'!$G$11,'Risk Range & Risk Matrix'!$H$11,IF(S31='Risk Range & Risk Matrix'!$G$10,'Risk Range & Risk Matrix'!$H$10,IF(S31='Risk Range & Risk Matrix'!$G$9,'Risk Range & Risk Matrix'!$H$9,IF(S31='Risk Range & Risk Matrix'!$G$8,'Risk Range & Risk Matrix'!$H$8,""))))) | V31: =IF(U31='Risk Range & Risk Matrix'!$I$6,'Risk Range & Risk Matrix'!$I$7,IF(U31='Risk Range & Risk Matrix'!$J$6,'Risk Range & Risk Matrix'!$J$7,IF(U31='Risk Range & Risk Matrix'!$K$6,'Risk Range & Risk Matrix'!$K$7,IF(U31='Risk Range & Risk Matrix'!$L$6,'Risk Range & Risk Matrix'!$L$7,IF(U31='Risk Range & Risk Matrix'!$M$6,'Risk Range & Risk Matrix'!$M$7,""))))) | W31: =IF(OR(T31="",V31=""),"empty",T31*V31) -> empty | X31: =W31 -> empty
B32: R24 | L32: =IF(K32='Risk Range & Risk Matrix'!$G$12,'Risk Range & Risk Matrix'!$H$12,IF(K32='Risk Range & Risk Matrix'!$G$11,'Risk Range & Risk Matrix'!$H$11,IF(K32='Risk Range & Risk Matrix'!$G$10,'Risk Range & Risk Matrix'!$H$10,IF(K32='Risk Range & Risk Matrix'!$G$9,'Risk Range & Risk Matrix'!$H$9,IF(K32='Risk Range & Risk Matrix'!$G$8,'Risk Range & Risk Matrix'!$H$8,""))))) | N32: =IF(M32='Risk Range & Risk Matrix'!$I$6,'Risk Range & Risk Matrix'!$I$7,IF(M32='Risk Range & Risk Matrix'!$J$6,'Risk Range & Risk Matrix'!$J$7,IF(M32='Risk Range & Risk Matrix'!$K$6,'Risk Range & Risk Matrix'!$K$7,IF(M32='Risk Range & Risk Matrix'!$L$6,'Risk Range & Risk Matrix'!$L$7,IF(M32='Risk Range & Risk Matrix'!$M$6,'Risk Range & Risk Matrix'!$M$7,""))))) | O32: =IF(OR(L32="",N32=""),"empty",L32*N32) -> empty | P32: =O32 -> empty | T32: =IF(S32='Risk Range & Risk Matrix'!$G$12,'Risk Range & Risk Matrix'!$H$12,IF(S32='Risk Range & Risk Matrix'!$G$11,'Risk Range & Risk Matrix'!$H$11,IF(S32='Risk Range & Risk Matrix'!$G$10,'Risk Range & Risk Matrix'!$H$10,IF(S32='Risk Range & Risk Matrix'!$G$9,'Risk Range & Risk Matrix'!$H$9,IF(S32='Risk Range & Risk Matrix'!$G$8,'Risk Range & Risk Matrix'!$H$8,""))))) | V32: =IF(U32='Risk Range & Risk Matrix'!$I$6,'Risk Range & Risk Matrix'!$I$7,IF(U32='Risk Range & Risk Matrix'!$J$6,'Risk Range & Risk Matrix'!$J$7,IF(U32='Risk Range & Risk Matrix'!$K$6,'Risk Range & Risk Matrix'!$K$7,IF(U32='Risk Range & Risk Matrix'!$L$6,'Risk Range & Risk Matrix'!$L$7,IF(U32='Risk Range & Risk Matrix'!$M$6,'Risk Range & Risk Matrix'!$M$7,""))))) | W32: =IF(OR(T32="",V32=""),"empty",T32*V32) -> empty | X32: =W32 -> empty
B33: R25 | L33: =IF(K33='Risk Range & Risk Matrix'!$G$12,'Risk Range & Risk Matrix'!$H$12,IF(K33='Risk Range & Risk Matrix'!$G$11,'Risk Range & Risk Matrix'!$H$11,IF(K33='Risk Range & Risk Matrix'!$G$10,'Risk Range & Risk Matrix'!$H$10,IF(K33='Risk Range & Risk Matrix'!$G$9,'Risk Range & Risk Matrix'!$H$9,IF(K33='Risk Range & Risk Matrix'!$G$8,'Risk Range & Risk Matrix'!$H$8,""))))) | N33: =IF(M33='Risk Range & Risk Matrix'!$I$6,'Risk Range & Risk Matrix'!$I$7,IF(M33='Risk Range & Risk Matrix'!$J$6,'Risk Range & Risk Matrix'!$J$7,IF(M33='Risk Range & Risk Matrix'!$K$6,'Risk Range & Risk Matrix'!$K$7,IF(M33='Risk Range & Risk Matrix'!$L$6,'Risk Range & Risk Matrix'!$L$7,IF(M33='Risk Range & Risk Matrix'!$M$6,'Risk Range & Risk Matrix'!$M$7,""))))) | O33: =IF(OR(L33="",N33=""),"empty",L33*N33) -> empty | P33: =O33 -> empty | T33: =IF(S33='Risk Range & Risk Matrix'!$G$12,'Risk Range & Risk Matrix'!$H$12,IF(S33='Risk Range & Risk Matrix'!$G$11,'Risk Range & Risk Matrix'!$H$11,IF(S33='Risk Range & Risk Matrix'!$G$10,'Risk Range & Risk Matrix'!$H$10,IF(S33='Risk Range & Risk Matrix'!$G$9,'Risk Range & Risk Matrix'!$H$9,IF(S33='Risk Range & Risk Matrix'!$G$8,'Risk Range & Risk Matrix'!$H$8,""))))) | V33: =IF(U33='Risk Range & Risk Matrix'!$I$6,'Risk Range & Risk Matrix'!$I$7,IF(U33='Risk Range & Risk Matrix'!$J$6,'Risk Range & Risk Matrix'!$J$7,IF(U33='Risk Range & Risk Matrix'!$K$6,'Risk Range & Risk Matrix'!$K$7,IF(U33='Risk Range & Risk Matrix'!$L$6,'Risk Range & Risk Matrix'!$L$7,IF(U33='Risk Range & Risk Matrix'!$M$6,'Risk Range & Risk Matrix'!$M$7,""))))) | W33: =IF(OR(T33="",V33=""),"empty",T33*V33) -> empty | X33: =W33 -> empty
B34: R26 | L34: =IF(K34='Risk Range & Risk Matrix'!$G$12,'Risk Range & Risk Matrix'!$H$12,IF(K34='Risk Range & Risk Matrix'!$G$11,'Risk Range & Risk Matrix'!$H$11,IF(K34='Risk Range & Risk Matrix'!$G$10,'Risk Range & Risk Matrix'!$H$10,IF(K34='Risk Range & Risk Matrix'!$G$9,'Risk Range & Risk Matrix'!$H$9,IF(K34='Risk Range & Risk Matrix'!$G$8,'Risk Range & Risk Matrix'!$H$8,""))))) | N34: =IF(M34='Risk Range & Risk Matrix'!$I$6,'Risk Range & Risk Matrix'!$I$7,IF(M34='Risk Range & Risk Matrix'!$J$6,'Risk Range & Risk Matrix'!$J$7,IF(M34='Risk Range & Risk Matrix'!$K$6,'Risk Range & Risk Matrix'!$K$7,IF(M34='Risk Range & Risk Matrix'!$L$6,'Risk Range & Risk Matrix'!$L$7,IF(M34='Risk Range & Risk Matrix'!$M$6,'Risk Range & Risk Matrix'!$M$7,""))))) | O34: =IF(OR(L34="",N34=""),"empty",L34*N34) -> empty | P34: =O34 -> empty | T34: =IF(S34='Risk Range & Risk Matrix'!$G$12,'Risk Range & Risk Matrix'!$H$12,IF(S34='Risk Range & Risk Matrix'!$G$11,'Risk Range & Risk Matrix'!$H$11,IF(S34='Risk Range & Risk Matrix'!$G$10,'Risk Range & Risk Matrix'!$H$10,IF(S34='Risk Range & Risk Matrix'!$G$9,'Risk Range & Risk Matrix'!$H$9,IF(S34='Risk Range & Risk Matrix'!$G$8,'Risk Range & Risk Matrix'!$H$8,""))))) | V34: =IF(U34='Risk Range & Risk Matrix'!$I$6,'Risk Range & Risk Matrix'!$I$7,IF(U34='Risk Range & Risk Matrix'!$J$6,'Risk Range & Risk Matrix'!$J$7,IF(U34='Risk Range & Risk Matrix'!$K$6,'Risk Range & Risk Matrix'!$K$7,IF(U34='Risk Range & Risk Matrix'!$L$6,'Risk Range & Risk Matrix'!$L$7,IF(U34='Risk Range & Risk Matrix'!$M$6,'Risk Range & Risk Matrix'!$M$7,""))))) | W34: =IF(OR(T34="",V34=""),"empty",T34*V34) -> empty | X34: =W34 -> empty
B35: R27 | L35: =IF(K35='Risk Range & Risk Matrix'!$G$12,'Risk Range & Risk Matrix'!$H$12,IF(K35='Risk Range & Risk Matrix'!$G$11,'Risk Range & Risk Matrix'!$H$11,IF(K35='Risk Range & Risk Matrix'!$G$10,'Risk Range & Risk Matrix'!$H$10,IF(K35='Risk Range & Risk Matrix'!$G$9,'Risk Range & Risk Matrix'!$H$9,IF(K35='Risk Range & Risk Matrix'!$G$8,'Risk Range & Risk Matrix'!$H$8,""))))) | N35: =IF(M35='Risk Range & Risk Matrix'!$I$6,'Risk Range & Risk Matrix'!$I$7,IF(M35='Risk Range & Risk Matrix'!$J$6,'Risk Range & Risk Matrix'!$J$7,IF(M35='Risk Range & Risk Matrix'!$K$6,'Risk Range & Risk Matrix'!$K$7,IF(M35='Risk Range & Risk Matrix'!$L$6,'Risk Range & Risk Matrix'!$L$7,IF(M35='Risk Range & Risk Matrix'!$M$6,'Risk Range & Risk Matrix'!$M$7,""))))) | O35: =IF(OR(L35="",N35=""),"empty",L35*N35) -> empty | P35: =O35 -> empty | T35: =IF(S35='Risk Range & Risk Matrix'!$G$12,'Risk Range & Risk Matrix'!$H$12,IF(S35='Risk Range & Risk Matrix'!$G$11,'Risk Range & Risk Matrix'!$H$11,IF(S35='Risk Range & Risk Matrix'!$G$10,'Risk Range & Risk Matrix'!$H$10,IF(S35='Risk Range & Risk Matrix'!$G$9,'Risk Range & Risk Matrix'!$H$9,IF(S35='Risk Range & Risk Matrix'!$G$8,'Risk Range & Risk Matrix'!$H$8,""))))) | V35: =IF(U35='Risk Range & Risk Matrix'!$I$6,'Risk Range & Risk Matrix'!$I$7,IF(U35='Risk Range & Risk Matrix'!$J$6,'Risk Range & Risk Matrix'!$J$7,IF(U35='Risk Range & Risk Matrix'!$K$6,'Risk Range & Risk Matrix'!$K$7,IF(U35='Risk Range & Risk Matrix'!$L$6,'Risk Range & Risk Matrix'!$L$7,IF(U35='Risk Range & Risk Matrix'!$M$6,'Risk Range & Risk Matrix'!$M$7,""))))) | W35: =IF(OR(T35="",V35=""),"empty",T35*V35) -> empty | X35: =W35 -> empty
B36: R28 | L36: =IF(K36='Risk Range & Risk Matrix'!$G$12,'Risk Range & Risk Matrix'!$H$12,IF(K36='Risk Range & Risk Matrix'!$G$11,'Risk Range & Risk Matrix'!$H$11,IF(K36='Risk Range & Risk Matrix'!$G$10,'Risk Range & Risk Matrix'!$H$10,IF(K36='Risk Range & Risk Matrix'!$G$9,'Risk Range & Risk Matrix'!$H$9,IF(K36='Risk Range & Risk Matrix'!$G$8,'Risk Range & Risk Matrix'!$H$8,""))))) | N36: =IF(M36='Risk Range & Risk Matrix'!$I$6,'Risk Range & Risk Matrix'!$I$7,IF(M36='Risk Range & Risk Matrix'!$J$6,'Risk Range & Risk Matrix'!$J$7,IF(M36='Risk Range & Risk Matrix'!$K$6,'Risk Range & Risk Matrix'!$K$7,IF(M36='Risk Range & Risk Matrix'!$L$6,'Risk Range & Risk Matrix'!$L$7,IF(M36='Risk Range & Risk Matrix'!$M$6,'Risk Range & Risk Matrix'!$M$7,""))))) | O36: =IF(OR(L36="",N36=""),"empty",L36*N36) -> empty | P36: =O36 -> empty | T36: =IF(S36='Risk Range & Risk Matrix'!$G$12,'Risk Range & Risk Matrix'!$H$12,IF(S36='Risk Range & Risk Matrix'!$G$11,'Risk Range & Risk Matrix'!$H$11,IF(S36='Risk Range & Risk Matrix'!$G$10,'Risk Range & Risk Matrix'!$H$10,IF(S36='Risk Range & Risk Matrix'!$G$9,'Risk Range & Risk Matrix'!$H$9,IF(S36='Risk Range & Risk Matrix'!$G$8,'Risk Range & Risk Matrix'!$H$8,""))))) | V36: =IF(U36='Risk Range & Risk Matrix'!$I$6,'Risk Range & Risk Matrix'!$I$7,IF(U36='Risk Range & Risk Matrix'!$J$6,'Risk Range & Risk Matrix'!$J$7,IF(U36='Risk Range & Risk Matrix'!$K$6,'Risk Range & Risk Matrix'!$K$7,IF(U36='Risk Range & Risk Matrix'!$L$6,'Risk Range & Risk Matrix'!$L$7,IF(U36='Risk Range & Risk Matrix'!$M$6,'Risk Range & Risk Matrix'!$M$7,""))))) | W36: =IF(OR(T36="",V36=""),"empty",T36*V36) -> empty | X36: =W36 -> empty
B37: R29 | L37: =IF(K37='Risk Range & Risk Matrix'!$G$12,'Risk Range & Risk Matrix'!$H$12,IF(K37='Risk Range & Risk Matrix'!$G$11,'Risk Range & Risk Matrix'!$H$11,IF(K37='Risk Range & Risk Matrix'!$G$10,'Risk Range & Risk Matrix'!$H$10,IF(K37='Risk Range & Risk Matrix'!$G$9,'Risk Range & Risk Matrix'!$H$9,IF(K37='Risk Range & Risk Matrix'!$G$8,'Risk Range & Risk Matrix'!$H$8,""))))) | N37: =IF(M37='Risk Range & Risk Matrix'!$I$6,'Risk Range & Risk Matrix'!$I$7,IF(M37='Risk Range & Risk Matrix'!$J$6,'Risk Range & Risk Matrix'!$J$7,IF(M37='Risk Range & Risk Matrix'!$K$6,'Risk Range & Risk Matrix'!$K$7,IF(M37='Risk Range & Risk Matrix'!$L$6,'Risk Range & Risk Matrix'!$L$7,IF(M37='Risk Range & Risk Matrix'!$M$6,'Risk Range & Risk Matrix'!$M$7,""))))) | O37: =IF(OR(L37="",N37=""),"empty",L37*N37) -> empty | P37: =O37 -> empty | T37: =IF(S37='Risk Range & Risk Matrix'!$G$12,'Risk Range & Risk Matrix'!$H$12,IF(S37='Risk Range & Risk Matrix'!$G$11,'Risk Range & Risk Matrix'!$H$11,IF(S37='Risk Range & Risk Matrix'!$G$10,'Risk Range & Risk Matrix'!$H$10,IF(S37='Risk Range & Risk Matrix'!$G$9,'Risk Range & Risk Matrix'!$H$9,IF(S37='Risk Range & Risk Matrix'!$G$8,'Risk Range & Risk Matrix'!$H$8,""))))) | V37: =IF(U37='Risk Range & Risk Matrix'!$I$6,'Risk Range & Risk Matrix'!$I$7,IF(U37='Risk Range & Risk Matrix'!$J$6,'Risk Range & Risk Matrix'!$J$7,IF(U37='Risk Range & Risk Matrix'!$K$6,'Risk Range & Risk Matrix'!$K$7,IF(U37='Risk Range & Risk Matrix'!$L$6,'Risk Range & Risk Matrix'!$L$7,IF(U37='Risk Range & Risk Matrix'!$M$6,'Risk Range & Risk Matrix'!$M$7,""))))) | W37: =IF(OR(T37="",V37=""),"empty",T37*V37) -> empty | X37: =W37 -> empty
B38: R30 | L38: =IF(K38='Risk Range & Risk Matrix'!$G$12,'Risk Range & Risk Matrix'!$H$12,IF(K38='Risk Range & Risk Matrix'!$G$11,'Risk Range & Risk Matrix'!$H$11,IF(K38='Risk Range & Risk Matrix'!$G$10,'Risk Range & Risk Matrix'!$H$10,IF(K38='Risk Range & Risk Matrix'!$G$9,'Risk Range & Risk Matrix'!$H$9,IF(K38='Risk Range & Risk Matrix'!$G$8,'Risk Range & Risk Matrix'!$H$8,""))))) | N38: =IF(M38='Risk Range & Risk Matrix'!$I$6,'Risk Range & Risk Matrix'!$I$7,IF(M38='Risk Range & Risk Matrix'!$J$6,'Risk Range & Risk Matrix'!$J$7,IF(M38='Risk Range & Risk Matrix'!$K$6,'Risk Range & Risk Matrix'!$K$7,IF(M38='Risk Range & Risk Matrix'!$L$6,'Risk Range & Risk Matrix'!$L$7,IF(M38='Risk Range & Risk Matrix'!$M$6,'Risk Range & Risk Matrix'!$M$7,""))))) | O38: =IF(OR(L38="",N38=""),"empty",L38*N38) -> empty | P38: =O38 -> empty | T38: =IF(S38='Risk Range & Risk Matrix'!$G$12,'Risk Range & Risk Matrix'!$H$12,IF(S38='Risk Range & Risk Matrix'!$G$11,'Risk Range & Risk Matrix'!$H$11,IF(S38='Risk Range & Risk Matrix'!$G$10,'Risk Range & Risk Matrix'!$H$10,IF(S38='Risk Range & Risk Matrix'!$G$9,'Risk Range & Risk Matrix'!$H$9,IF(S38='Risk Range & Risk Matrix'!$G$8,'Risk Range & Risk Matrix'!$H$8,""))))) | V38: =IF(U38='Risk Range & Risk Matrix'!$I$6,'Risk Range & Risk Matrix'!$I$7,IF(U38='Risk Range & Risk Matrix'!$J$6,'Risk Range & Risk Matrix'!$J$7,IF(U38='Risk Range & Risk Matrix'!$K$6,'Risk Range & Risk Matrix'!$K$7,IF(U38='Risk Range & Risk Matrix'!$L$6,'Risk Range & Risk Matrix'!$L$7,IF(U38='Risk Range & Risk Matrix'!$M$6,'Risk Range & Risk Matrix'!$M$7,""))))) | W38: =IF(OR(T38="",V38=""),"empty",T38*V38) -> empty | X38: =W38 -> empty
B39: R31 | L39: =IF(K39='Risk Range & Risk Matrix'!$G$12,'Risk Range & Risk Matrix'!$H$12,IF(K39='Risk Range & Risk Matrix'!$G$11,'Risk Range & Risk Matrix'!$H$11,IF(K39='Risk Range & Risk Matrix'!$G$10,'Risk Range & Risk Matrix'!$H$10,IF(K39='Risk Range & Risk Matrix'!$G$9,'Risk Range & Risk Matrix'!$H$9,IF(K39='Risk Range & Risk Matrix'!$G$8,'Risk Range & Risk Matrix'!$H$8,""))))) | N39: =IF(M39='Risk Range & Risk Matrix'!$I$6,'Risk Range & Risk Matrix'!$I$7,IF(M39='Risk Range & Risk Matrix'!$J$6,'Risk Range & Risk Matrix'!$J$7,IF(M39='Risk Range & Risk Matrix'!$K$6,'Risk Range & Risk Matrix'!$K$7,IF(M39='Risk Range & Risk Matrix'!$L$6,'Risk Range & Risk Matrix'!$L$7,IF(M39='Risk Range & Risk Matrix'!$M$6,'Risk Range & Risk Matrix'!$M$7,""))))) | O39: =IF(OR(L39="",N39=""),"empty",L39*N39) -> empty | P39: =O39 -> empty | T39: =IF(S39='Risk Range & Risk Matrix'!$G$12,'Risk Range & Risk Matrix'!$H$12,IF(S39='Risk Range & Risk Matrix'!$G$11,'Risk Range & Risk Matrix'!$H$11,IF(S39='Risk Range & Risk Matrix'!$G$10,'Risk Range & Risk Matrix'!$H$10,IF(S39='Risk Range & Risk Matrix'!$G$9,'Risk Range & Risk Matrix'!$H$9,IF(S39='Risk Range & Risk Matrix'!$G$8,'Risk Range & Risk Matrix'!$H$8,""))))) | V39: =IF(U39='Risk Range & Risk Matrix'!$I$6,'Risk Range & Risk Matrix'!$I$7,IF(U39='Risk Range & Risk Matrix'!$J$6,'Risk Range & Risk Matrix'!$J$7,IF(U39='Risk Range & Risk Matrix'!$K$6,'Risk Range & Risk Matrix'!$K$7,IF(U39='Risk Range & Risk Matrix'!$L$6,'Risk Range & Risk Matrix'!$L$7,IF(U39='Risk Range & Risk Matrix'!$M$6,'Risk Range & Risk Matrix'!$M$7,""))))) | W39: =IF(OR(T39="",V39=""),"empty",T39*V39) -> empty | X39: =W39 -> empty
B40: R32 | L40: =IF(K40='Risk Range & Risk Matrix'!$G$12,'Risk Range & Risk Matrix'!$H$12,IF(K40='Risk Range & Risk Matrix'!$G$11,'Risk Range & Risk Matrix'!$H$11,IF(K40='Risk Range & Risk Matrix'!$G$10,'Risk Range & Risk Matrix'!$H$10,IF(K40='Risk Range & Risk Matrix'!$G$9,'Risk Range & Risk Matrix'!$H$9,IF(K40='Risk Range & Risk Matrix'!$G$8,'Risk Range & Risk Matrix'!$H$8,""))))) | N40: =IF(M40='Risk Range & Risk Matrix'!$I$6,'Risk Range & Risk Matrix'!$I$7,IF(M40='Risk Range & Risk Matrix'!$J$6,'Risk Range & Risk Matrix'!$J$7,IF(M40='Risk Range & Risk Matrix'!$K$6,'Risk Range & Risk Matrix'!$K$7,IF(M40='Risk Range & Risk Matrix'!$L$6,'Risk Range & Risk Matrix'!$L$7,IF(M40='Risk Range & Risk Matrix'!$M$6,'Risk Range & Risk Matrix'!$M$7,""))))) | O40: =IF(OR(L40="",N40=""),"empty",L40*N40) -> empty | P40: =O40 -> empty | T40: =IF(S40='Risk Range & Risk Matrix'!$G$12,'Risk Range & Risk Matrix'!$H$12,IF(S40='Risk Range & Risk Matrix'!$G$11,'Risk Range & Risk Matrix'!$H$11,IF(S40='Risk Range & Risk Matrix'!$G$10,'Risk Range & Risk Matrix'!$H$10,IF(S40='Risk Range & Risk Matrix'!$G$9,'Risk Range & Risk Matrix'!$H$9,IF(S40='Risk Range & Risk Matrix'!$G$8,'Risk Range & Risk Matrix'!$H$8,""))))) | V40: =IF(U40='Risk Range & Risk Matrix'!$I$6,'Risk Range & Risk Matrix'!$I$7,IF(U40='Risk Range & Risk Matrix'!$J$6,'Risk Range & Risk Matrix'!$J$7,IF(U40='Risk Range & Risk Matrix'!$K$6,'Risk Range & Risk Matrix'!$K$7,IF(U40='Risk Range & Risk Matrix'!$L$6,'Risk Range & Risk Matrix'!$L$7,IF(U40='Risk Range & Risk Matrix'!$M$6,'Risk Range & Risk Matrix'!$M$7,""))))) | W40: =IF(OR(T40="",V40=""),"empty",T40*V40) -> empty | X40: =W40 -> empty
... B109: Rn | L109: =IF(K109='Risk Range & Risk Matrix'!$G$12,'Risk Range & Risk Matrix'!$H$12,IF(K109='Risk Range & Risk Matrix'!$G$11,'Risk Range & Risk Matrix'!$H$11,IF(K109='Risk Range & Risk Matrix'!$G$10,'Risk Range & Risk Matrix'!$H$10,IF(K109='Risk Range & Risk Matrix'!$G$9,'Risk Range & Risk Matrix'!$H$9,IF(K109='Risk Range & Risk Matrix'!$G$8,'Risk Range & Risk Matrix'!$H$8,""))))) | N109: =IF(M109='Risk Range & Risk Matrix'!$I$6,'Risk Range & Risk Matrix'!$I$7,IF(M109='Risk Range & Risk Matrix'!$J$6,'Risk Range & Risk Matrix'!$J$7,IF(M109='Risk Range & Risk Matrix'!$K$6,'Risk Range & Risk Matrix'!$K$7,IF(M109='Risk Range & Risk Matrix'!$L$6,'Risk Range & Risk Matrix'!$L$7,IF(M109='Risk Range & Risk Matrix'!$M$6,'Risk Range & Risk Matrix'!$M$7,""))))) | O109: =IF(OR(L109="",N109=""),"empty",L109*N109) -> empty | P109: =O109 -> empty | T109: =IF(S109='Risk Range & Risk Matrix'!$G$12,'Risk Range & Risk Matrix'!$H$12,IF(S109='Risk Range & Risk Matrix'!$G$11,'Risk Range & Risk Matrix'!$H$11,IF(S109='Risk Range & Risk Matrix'!$G$10,'Risk Range & Risk Matrix'!$H$10,IF(S109='Risk Range & Risk Matrix'!$G$9,'Risk Range & Risk Matrix'!$H$9,IF(S109='Risk Range & Risk Matrix'!$G$8,'Risk Range & Risk Matrix'!$H$8,""))))) | V109: =IF(U109='Risk Range & Risk Matrix'!$I$6,'Risk Range & Risk Matrix'!$I$7,IF(U109='Risk Range & Risk Matrix'!$J$6,'Risk Range & Risk Matrix'!$J$7,IF(U109='Risk Range & Risk Matrix'!$K$6,'Risk Range & Risk Matrix'!$K$7,IF(U109='Risk Range & Risk Matrix'!$L$6,'Risk Range & Risk Matrix'!$L$7,IF(U109='Risk Range & Risk Matrix'!$M$6,'Risk Range & Risk Matrix'!$M$7,""))))) | W109: =IF(OR(T109="",V109=""),"empty",T109*V109) -> empty | X109: =W109 -> empty

Sheet Risk Range & Risk Matrix
B6: Editable fields | G6: Risk Matrix | I6: Insignificant | J6: Minor | K6: Moderate | L6: Major | M6: Catastrophic
B7: Risk Range | I7: 1 | J7: 2 | K7: 3 | L7: 4 | M7: 5
B8: Risk Range | C8: Min value | D8: Max value | E8: Description | G8: Almost certain | H8: 5 | I8: =I7*$H$8 -> 5 | J8: =J7*$H$8 -> 10 | K8: =K7*$H$8 -> 15 | L8: =L7*$H$8 -> 20 | M8: =M7*$H$8 -> 25
B9: Extreme risk | C9: =D10+1 -> 23 | D9: =H8*M7 -> 25 | E9: Possible project faliure | G9: Very likely | H9: 4 | I9: =I7*$H$9 -> 4 | J9: =J7*$H$9 -> 8 | K9: =K7*$H$9 -> 12 | L9: =L7*$H$9 -> 16 | M9: =M7*$H$9 -> 20
B10: High risk | C10: =D11+1 -> 16 | D10: 22 | E10: Significant delay in schedule or need for additional resources and/or planning | G10: Possible | H10: 2 | I10: =I7*$H$10 -> 2 | J10: =J7*$H$10 -> 4 | K10: =K7*$H$10 -> 6 | L10: =L7*$H$10 -> 8 | M10: =M7*$H$10 -> 10
B11: Medium risk | C11: =D12+1 -> 6 | D11: 15 | E11: Bearable delay in schedule or budget. | G11: Likely | H11: 2 | I11: =I7*$H$11 -> 2 | J11: =J7*$H$11 -> 4 | K11: =K7*$H$11 -> 6 | L11: =L7*$H$11 -> 8 | M11: =M7*$H$11 -> 10
B12: Low risk | C12: =I7*H12 -> 1 | D12: 5 | E12: Sufficient contingency built into the project to contain risk | G12: Unlikely | H12: 1 | I12: =I7*$H$12 -> 1 | J12: =J7*$H$12 -> 2 | K12: =K7*$H$12 -> 3 | L12: =L7*$H$12 -> 4 | M12: =M7*$H$12 -> 5

Sheet Lists
A1: Category | C1: Likelihood | D1: Impact | E1: Treatment | F1: Type | G1: Urgency level | H1: Characteristic
A2: Technical | B2: 1 | C2: Unlikely | D2: Insignificant | E2: Avoid | F2: Internal | G2: High | H2: Positive
A3: Cost | B3: 2 | C3: Likely | D3: Minor | E3: Transfer | F3: External | G3: Medium | H3: Negative
A4: Schedule | B4: 3 | C4: Possible | D4: Moderate | E4: Mitigate | G4: Low
A5: Contractual | B5: 4 | C5: Very likely | D5: Major | E5: Accept
